-- Logs begin at Wed 2019-01-02 13:59:50 PST, end at Wed 2019-01-02 14:20:39 PST. --
Jan 02 14:00:41 jfz1r03h11 devstack@placement-api.service[14363]: DEBUG placement.requestlog [req-86df91ba-eec0-4c01-9290-971c6588cfe8 req-54d6b511-1019-48d7-a58b-7cf90adc9d5a service placement] Starting request: 172.16.3.11 "GET /placement/resource_providers/ec763e10-0c86-43eb-a2e0-25e429390a15/allocations" {{(pid=14380) __call__ /opt/stack/placement/placement/requestlog.py:38}}
Jan 02 14:00:41 jfz1r03h11 devstack@placement-api.service[14363]: DEBUG placement.wsgi_wrapper [req-86df91ba-eec0-4c01-9290-971c6588cfe8 req-54d6b511-1019-48d7-a58b-7cf90adc9d5a service placement] Placement API returning an error response: Resource provider 'ec763e10-0c86-43eb-a2e0-25e429390a15' not found: No resource provider with uuid ec763e10-0c86-43eb-a2e0-25e429390a15 found {{(pid=14380) call_func /opt/stack/placement/placement/wsgi_wrapper.py:31}}
Jan 02 14:00:41 jfz1r03h11 devstack@placement-api.service[14363]: INFO placement.requestlog [req-86df91ba-eec0-4c01-9290-971c6588cfe8 req-54d6b511-1019-48d7-a58b-7cf90adc9d5a service placement] 172.16.3.11 "GET /placement/resource_providers/ec763e10-0c86-43eb-a2e0-25e429390a15/allocations" status: 404 len: 303 microversion: 1.0
Jan 02 14:00:41 jfz1r03h11 devstack@placement-api.service[14363]: [pid: 14380|app: 0|req: 28/490] 172.16.3.11 () {62 vars in 1465 bytes} [Wed Jan  2 14:00:41 2019] GET /placement/resource_providers/ec763e10-0c86-43eb-a2e0-25e429390a15/allocations => generated 303 bytes in 15 msecs (HTTP/1.1 404) 6 headers in 231 bytes (1 switches on core 0)
Jan 02 14:00:41 jfz1r03h11 devstack@placement-api.service[14363]: DEBUG placement.requestlog [req-86df91ba-eec0-4c01-9290-971c6588cfe8 req-9a7776be-78e9-4da2-901a-c46e91179cd8 service placement] Starting request: 172.16.3.11 "GET /placement/resource_providers?in_tree=ec763e10-0c86-43eb-a2e0-25e429390a15" {{(pid=14381) __call__ /opt/stack/placement/placement/requestlog.py:38}}
Jan 02 14:00:41 jfz1r03h11 devstack@placement-api.service[14363]: INFO placement.requestlog [req-86df91ba-eec0-4c01-9290-971c6588cfe8 req-9a7776be-78e9-4da2-901a-c46e91179cd8 service placement] 172.16.3.11 "GET /placement/resource_providers?in_tree=ec763e10-0c86-43eb-a2e0-25e429390a15" status: 200 len: 26 microversion: 1.14
Jan 02 14:00:41 jfz1r03h11 devstack@placement-api.service[14363]: [pid: 14381|app: 0|req: 28/491] 172.16.3.11 () {64 vars in 1451 bytes} [Wed Jan  2 14:00:41 2019] GET /placement/resource_providers?in_tree=ec763e10-0c86-43eb-a2e0-25e429390a15 => generated 26 bytes in 20 msecs (HTTP/1.1 200) 6 headers in 224 bytes (1 switches on core 0)
Jan 02 14:00:41 jfz1r03h11 devstack@placement-api.service[14363]: DEBUG placement.requestlog [req-86df91ba-eec0-4c01-9290-971c6588cfe8 req-9dc0262a-ee1b-4a5d-93ef-310d6e72d9b3 service placement] Starting request: 172.16.3.11 "POST /placement/resource_providers" {{(pid=14376) __call__ /opt/stack/placement/placement/requestlog.py:38}}
Jan 02 14:00:41 jfz1r03h11 devstack@placement-api.service[14363]: DEBUG placement.wsgi_wrapper [req-86df91ba-eec0-4c01-9290-971c6588cfe8 req-9dc0262a-ee1b-4a5d-93ef-310d6e72d9b3 service placement] Placement API returning an error response: Conflicting resource provider name: jfz1r03h11 already exists. {{(pid=14376) call_func /opt/stack/placement/placement/wsgi_wrapper.py:31}}
Jan 02 14:00:41 jfz1r03h11 devstack@placement-api.service[14363]: INFO placement.requestlog [req-86df91ba-eec0-4c01-9290-971c6588cfe8 req-9dc0262a-ee1b-4a5d-93ef-310d6e72d9b3 service placement] 172.16.3.11 "POST /placement/resource_providers" status: 409 len: 249 microversion: 1.20
Jan 02 14:00:41 jfz1r03h11 devstack@placement-api.service[14363]: [pid: 14376|app: 0|req: 28/492] 172.16.3.11 () {68 vars in 1415 bytes} [Wed Jan  2 14:00:41 2019] POST /placement/resource_providers => generated 249 bytes in 16 msecs (HTTP/1.1 409) 6 headers in 231 bytes (1 switches on core 0)
Jan 02 14:01:43 jfz1r03h11 devstack@placement-api.service[14363]: DEBUG placement.requestlog [req-964649f1-8f14-4bc4-8047-433a3a5c69f7 req-4acb5d53-3ece-4c54-be6e-ca42d4248b79 service placement] Starting request: 172.16.3.11 "GET /placement/resource_providers/ec763e10-0c86-43eb-a2e0-25e429390a15/allocations" {{(pid=14369) __call__ /opt/stack/placement/placement/requestlog.py:38}}
Jan 02 14:01:43 jfz1r03h11 devstack@placement-api.service[14363]: DEBUG placement.wsgi_wrapper [req-964649f1-8f14-4bc4-8047-433a3a5c69f7 req-4acb5d53-3ece-4c54-be6e-ca42d4248b79 service placement] Placement API returning an error response: Resource provider 'ec763e10-0c86-43eb-a2e0-25e429390a15' not found: No resource provider with uuid ec763e10-0c86-43eb-a2e0-25e429390a15 found {{(pid=14369) call_func /opt/stack/placement/placement/wsgi_wrapper.py:31}}
Jan 02 14:01:43 jfz1r03h11 devstack@placement-api.service[14363]: INFO placement.requestlog [req-964649f1-8f14-4bc4-8047-433a3a5c69f7 req-4acb5d53-3ece-4c54-be6e-ca42d4248b79 service placement] 172.16.3.11 "GET /placement/resource_providers/ec763e10-0c86-43eb-a2e0-25e429390a15/allocations" status: 404 len: 303 microversion: 1.0
Jan 02 14:01:43 jfz1r03h11 devstack@placement-api.service[14363]: [pid: 14369|app: 0|req: 28/493] 172.16.3.11 () {62 vars in 1465 bytes} [Wed Jan  2 14:01:43 2019] GET /placement/resource_providers/ec763e10-0c86-43eb-a2e0-25e429390a15/allocations => generated 303 bytes in 16 msecs (HTTP/1.1 404) 6 headers in 231 bytes (1 switches on core 0)
Jan 02 14:01:43 jfz1r03h11 devstack@placement-api.service[14363]: DEBUG placement.requestlog [req-964649f1-8f14-4bc4-8047-433a3a5c69f7 req-057baf8d-833e-405d-b059-67e6a558ace3 service placement] Starting request: 172.16.3.11 "GET /placement/resource_providers?in_tree=ec763e10-0c86-43eb-a2e0-25e429390a15" {{(pid=14367) __call__ /opt/stack/placement/placement/requestlog.py:38}}
Jan 02 14:01:43 jfz1r03h11 devstack@placement-api.service[14363]: INFO placement.requestlog [req-964649f1-8f14-4bc4-8047-433a3a5c69f7 req-057baf8d-833e-405d-b059-67e6a558ace3 service placement] 172.16.3.11 "GET /placement/resource_providers?in_tree=ec763e10-0c86-43eb-a2e0-25e429390a15" status: 200 len: 26 microversion: 1.14
Jan 02 14:01:43 jfz1r03h11 devstack@placement-api.service[14363]: [pid: 14367|app: 0|req: 28/494] 172.16.3.11 () {64 vars in 1451 bytes} [Wed Jan  2 14:01:43 2019] GET /placement/resource_providers?in_tree=ec763e10-0c86-43eb-a2e0-25e429390a15 => generated 26 bytes in 19 msecs (HTTP/1.1 200) 6 headers in 224 bytes (1 switches on core 0)
Jan 02 14:01:43 jfz1r03h11 devstack@placement-api.service[14363]: DEBUG placement.requestlog [req-964649f1-8f14-4bc4-8047-433a3a5c69f7 req-5e5ec8fc-057a-413e-b948-55974e4033a2 service placement] Starting request: 172.16.3.11 "POST /placement/resource_providers" {{(pid=14370) __call__ /opt/stack/placement/placement/requestlog.py:38}}
Jan 02 14:01:43 jfz1r03h11 devstack@placement-api.service[14363]: DEBUG placement.wsgi_wrapper [req-964649f1-8f14-4bc4-8047-433a3a5c69f7 req-5e5ec8fc-057a-413e-b948-55974e4033a2 service placement] Placement API returning an error response: Conflicting resource provider name: jfz1r03h11 already exists. {{(pid=14370) call_func /opt/stack/placement/placement/wsgi_wrapper.py:31}}
Jan 02 14:01:43 jfz1r03h11 devstack@placement-api.service[14363]: INFO placement.requestlog [req-964649f1-8f14-4bc4-8047-433a3a5c69f7 req-5e5ec8fc-057a-413e-b948-55974e4033a2 service placement] 172.16.3.11 "POST /placement/resource_providers" status: 409 len: 249 microversion: 1.20
Jan 02 14:01:43 jfz1r03h11 devstack@placement-api.service[14363]: [pid: 14370|app: 0|req: 28/495] 172.16.3.11 () {68 vars in 1415 bytes} [Wed Jan  2 14:01:43 2019] POST /placement/resource_providers => generated 249 bytes in 15 msecs (HTTP/1.1 409) 6 headers in 231 bytes (1 switches on core 0)
Jan 02 14:02:45 jfz1r03h11 devstack@placement-api.service[14363]: DEBUG placement.requestlog [req-6c9c5e8b-3f75-4399-a747-716f1d05fee3 req-360b9c6a-c43a-4596-af64-ac0a909f9159 service placement] Starting request: 172.16.3.11 "GET /placement/resource_providers/ec763e10-0c86-43eb-a2e0-25e429390a15/allocations" {{(pid=14379) __call__ /opt/stack/placement/placement/requestlog.py:38}}
Jan 02 14:02:45 jfz1r03h11 devstack@placement-api.service[14363]: DEBUG placement.wsgi_wrapper [req-6c9c5e8b-3f75-4399-a747-716f1d05fee3 req-360b9c6a-c43a-4596-af64-ac0a909f9159 service placement] Placement API returning an error response: Resource provider 'ec763e10-0c86-43eb-a2e0-25e429390a15' not found: No resource provider with uuid ec763e10-0c86-43eb-a2e0-25e429390a15 found {{(pid=14379) call_func /opt/stack/placement/placement/wsgi_wrapper.py:31}}
Jan 02 14:02:45 jfz1r03h11 devstack@placement-api.service[14363]: INFO placement.requestlog [req-6c9c5e8b-3f75-4399-a747-716f1d05fee3 req-360b9c6a-c43a-4596-af64-ac0a909f9159 service placement] 172.16.3.11 "GET /placement/resource_providers/ec763e10-0c86-43eb-a2e0-25e429390a15/allocations" status: 404 len: 303 microversion: 1.0
Jan 02 14:02:45 jfz1r03h11 devstack@placement-api.service[14363]: [pid: 14379|app: 0|req: 28/496] 172.16.3.11 () {62 vars in 1465 bytes} [Wed Jan  2 14:02:45 2019] GET /placement/resource_providers/ec763e10-0c86-43eb-a2e0-25e429390a15/allocations => generated 303 bytes in 328 msecs (HTTP/1.1 404) 6 headers in 231 bytes (1 switches on core 0)
Jan 02 14:02:45 jfz1r03h11 devstack@placement-api.service[14363]: DEBUG placement.requestlog [req-6c9c5e8b-3f75-4399-a747-716f1d05fee3 req-0fac745d-914f-4832-beaf-2ed584415047 service placement] Starting request: 172.16.3.11 "GET /placement/resource_providers?in_tree=ec763e10-0c86-43eb-a2e0-25e429390a15" {{(pid=14373) __call__ /opt/stack/placement/placement/requestlog.py:38}}
Jan 02 14:02:45 jfz1r03h11 devstack@placement-api.service[14363]: INFO placement.requestlog [req-6c9c5e8b-3f75-4399-a747-716f1d05fee3 req-0fac745d-914f-4832-beaf-2ed584415047 service placement] 172.16.3.11 "GET /placement/resource_providers?in_tree=ec763e10-0c86-43eb-a2e0-25e429390a15" status: 200 len: 26 microversion: 1.14
Jan 02 14:02:45 jfz1r03h11 devstack@placement-api.service[14363]: [pid: 14373|app: 0|req: 28/497] 172.16.3.11 () {64 vars in 1451 bytes} [Wed Jan  2 14:02:45 2019] GET /placement/resource_providers?in_tree=ec763e10-0c86-43eb-a2e0-25e429390a15 => generated 26 bytes in 17 msecs (HTTP/1.1 200) 6 headers in 224 bytes (1 switches on core 0)
Jan 02 14:02:45 jfz1r03h11 devstack@placement-api.service[14363]: DEBUG placement.requestlog [req-6c9c5e8b-3f75-4399-a747-716f1d05fee3 req-1d173d1b-ef02-4cb2-9525-d3ec30e6def2 service placement] Starting request: 172.16.3.11 "POST /placement/resource_providers" {{(pid=14377) __call__ /opt/stack/placement/placement/requestlog.py:38}}
Jan 02 14:02:45 jfz1r03h11 devstack@placement-api.service[14363]: DEBUG placement.wsgi_wrapper [req-6c9c5e8b-3f75-4399-a747-716f1d05fee3 req-1d173d1b-ef02-4cb2-9525-d3ec30e6def2 service placement] Placement API returning an error response: Conflicting resource provider name: jfz1r03h11 already exists. {{(pid=14377) call_func /opt/stack/placement/placement/wsgi_wrapper.py:31}}
Jan 02 14:02:45 jfz1r03h11 devstack@placement-api.service[14363]: INFO placement.requestlog [req-6c9c5e8b-3f75-4399-a747-716f1d05fee3 req-1d173d1b-ef02-4cb2-9525-d3ec30e6def2 service placement] 172.16.3.11 "POST /placement/resource_providers" status: 409 len: 249 microversion: 1.20
Jan 02 14:02:45 jfz1r03h11 devstack@placement-api.service[14363]: [pid: 14377|app: 0|req: 28/498] 172.16.3.11 () {68 vars in 1415 bytes} [Wed Jan  2 14:02:45 2019] POST /placement/resource_providers => generated 249 bytes in 14 msecs (HTTP/1.1 409) 6 headers in 231 bytes (2 switches on core 0)
Jan 02 14:03:45 jfz1r03h11 devstack@placement-api.service[14363]: DEBUG placement.requestlog [req-0d02f9e6-75dc-4557-9e98-60868243d78d req-01ad628e-52fc-46f3-86e4-cb758e64730f service placement] Starting request: 172.16.3.11 "GET /placement/resource_providers/ec763e10-0c86-43eb-a2e0-25e429390a15/allocations" {{(pid=14383) __call__ /opt/stack/placement/placement/requestlog.py:38}}
Jan 02 14:03:45 jfz1r03h11 devstack@placement-api.service[14363]: DEBUG placement.wsgi_wrapper [req-0d02f9e6-75dc-4557-9e98-60868243d78d req-01ad628e-52fc-46f3-86e4-cb758e64730f service placement] Placement API returning an error response: Resource provider 'ec763e10-0c86-43eb-a2e0-25e429390a15' not found: No resource provider with uuid ec763e10-0c86-43eb-a2e0-25e429390a15 found {{(pid=14383) call_func /opt/stack/placement/placement/wsgi_wrapper.py:31}}
Jan 02 14:03:45 jfz1r03h11 devstack@placement-api.service[14363]: INFO placement.requestlog [req-0d02f9e6-75dc-4557-9e98-60868243d78d req-01ad628e-52fc-46f3-86e4-cb758e64730f service placement] 172.16.3.11 "GET /placement/resource_providers/ec763e10-0c86-43eb-a2e0-25e429390a15/allocations" status: 404 len: 303 microversion: 1.0
Jan 02 14:03:45 jfz1r03h11 devstack@placement-api.service[14363]: [pid: 14383|app: 0|req: 28/499] 172.16.3.11 () {62 vars in 1465 bytes} [Wed Jan  2 14:03:45 2019] GET /placement/resource_providers/ec763e10-0c86-43eb-a2e0-25e429390a15/allocations => generated 303 bytes in 15 msecs (HTTP/1.1 404) 6 headers in 231 bytes (1 switches on core 0)
Jan 02 14:03:45 jfz1r03h11 devstack@placement-api.service[14363]: DEBUG placement.requestlog [req-0d02f9e6-75dc-4557-9e98-60868243d78d req-e02f9f82-bf75-4707-ae3a-c82a0ae627e5 service placement] Starting request: 172.16.3.11 "GET /placement/resource_providers?in_tree=ec763e10-0c86-43eb-a2e0-25e429390a15" {{(pid=14368) __call__ /opt/stack/placement/placement/requestlog.py:38}}
Jan 02 14:03:45 jfz1r03h11 devstack@placement-api.service[14363]: INFO placement.requestlog [req-0d02f9e6-75dc-4557-9e98-60868243d78d req-e02f9f82-bf75-4707-ae3a-c82a0ae627e5 service placement] 172.16.3.11 "GET /placement/resource_providers?in_tree=ec763e10-0c86-43eb-a2e0-25e429390a15" status: 200 len: 26 microversion: 1.14
Jan 02 14:03:45 jfz1r03h11 devstack@placement-api.service[14363]: [pid: 14368|app: 0|req: 28/500] 172.16.3.11 () {64 vars in 1451 bytes} [Wed Jan  2 14:03:45 2019] GET /placement/resource_providers?in_tree=ec763e10-0c86-43eb-a2e0-25e429390a15 => generated 26 bytes in 19 msecs (HTTP/1.1 200) 6 headers in 224 bytes (1 switches on core 0)
Jan 02 14:03:45 jfz1r03h11 devstack@placement-api.service[14363]: DEBUG placement.requestlog [req-0d02f9e6-75dc-4557-9e98-60868243d78d req-95f405eb-48de-44aa-9ab9-f88420bcd11a service placement] Starting request: 172.16.3.11 "POST /placement/resource_providers" {{(pid=14382) __call__ /opt/stack/placement/placement/requestlog.py:38}}
Jan 02 14:03:45 jfz1r03h11 devstack@placement-api.service[14363]: DEBUG placement.wsgi_wrapper [req-0d02f9e6-75dc-4557-9e98-60868243d78d req-95f405eb-48de-44aa-9ab9-f88420bcd11a service placement] Placement API returning an error response: Conflicting resource provider name: jfz1r03h11 already exists. {{(pid=14382) call_func /opt/stack/placement/placement/wsgi_wrapper.py:31}}
Jan 02 14:03:45 jfz1r03h11 devstack@placement-api.service[14363]: INFO placement.requestlog [req-0d02f9e6-75dc-4557-9e98-60868243d78d req-95f405eb-48de-44aa-9ab9-f88420bcd11a service placement] 172.16.3.11 "POST /placement/resource_providers" status: 409 len: 249 microversion: 1.20
Jan 02 14:03:45 jfz1r03h11 devstack@placement-api.service[14363]: [pid: 14382|app: 0|req: 28/501] 172.16.3.11 () {68 vars in 1415 bytes} [Wed Jan  2 14:03:45 2019] POST /placement/resource_providers => generated 249 bytes in 15 msecs (HTTP/1.1 409) 6 headers in 231 bytes (1 switches on core 0)
Jan 02 14:04:47 jfz1r03h11 devstack@placement-api.service[14363]: DEBUG placement.requestlog [req-9f33e658-e4d8-48f2-ae04-0c42cf4f0089 req-14cadbec-c2eb-48df-9661-b464a9ece094 service placement] Starting request: 172.16.3.11 "GET /placement/resource_providers/ec763e10-0c86-43eb-a2e0-25e429390a15/allocations" {{(pid=14384) __call__ /opt/stack/placement/placement/requestlog.py:38}}
Jan 02 14:04:47 jfz1r03h11 devstack@placement-api.service[14363]: DEBUG placement.wsgi_wrapper [req-9f33e658-e4d8-48f2-ae04-0c42cf4f0089 req-14cadbec-c2eb-48df-9661-b464a9ece094 service placement] Placement API returning an error response: Resource provider 'ec763e10-0c86-43eb-a2e0-25e429390a15' not found: No resource provider with uuid ec763e10-0c86-43eb-a2e0-25e429390a15 found {{(pid=14384) call_func /opt/stack/placement/placement/wsgi_wrapper.py:31}}
Jan 02 14:04:47 jfz1r03h11 devstack@placement-api.service[14363]: INFO placement.requestlog [req-9f33e658-e4d8-48f2-ae04-0c42cf4f0089 req-14cadbec-c2eb-48df-9661-b464a9ece094 service placement] 172.16.3.11 "GET /placement/resource_providers/ec763e10-0c86-43eb-a2e0-25e429390a15/allocations" status: 404 len: 303 microversion: 1.0
Jan 02 14:04:47 jfz1r03h11 devstack@placement-api.service[14363]: [pid: 14384|app: 0|req: 28/502] 172.16.3.11 () {62 vars in 1465 bytes} [Wed Jan  2 14:04:47 2019] GET /placement/resource_providers/ec763e10-0c86-43eb-a2e0-25e429390a15/allocations => generated 303 bytes in 15 msecs (HTTP/1.1 404) 6 headers in 231 bytes (1 switches on core 0)
Jan 02 14:04:47 jfz1r03h11 devstack@placement-api.service[14363]: DEBUG placement.requestlog [req-9f33e658-e4d8-48f2-ae04-0c42cf4f0089 req-d097b86c-73fd-4f84-a7d7-4f7a6efd71e5 service placement] Starting request: 172.16.3.11 "GET /placement/resource_providers?in_tree=ec763e10-0c86-43eb-a2e0-25e429390a15" {{(pid=14378) __call__ /opt/stack/placement/placement/requestlog.py:38}}
Jan 02 14:04:47 jfz1r03h11 devstack@placement-api.service[14363]: INFO placement.requestlog [req-9f33e658-e4d8-48f2-ae04-0c42cf4f0089 req-d097b86c-73fd-4f84-a7d7-4f7a6efd71e5 service placement] 172.16.3.11 "GET /placement/resource_providers?in_tree=ec763e10-0c86-43eb-a2e0-25e429390a15" status: 200 len: 26 microversion: 1.14
Jan 02 14:04:47 jfz1r03h11 devstack@placement-api.service[14363]: [pid: 14378|app: 0|req: 28/503] 172.16.3.11 () {64 vars in 1451 bytes} [Wed Jan  2 14:04:47 2019] GET /placement/resource_providers?in_tree=ec763e10-0c86-43eb-a2e0-25e429390a15 => generated 26 bytes in 16 msecs (HTTP/1.1 200) 6 headers in 224 bytes (1 switches on core 0)
Jan 02 14:04:47 jfz1r03h11 devstack@placement-api.service[14363]: DEBUG placement.requestlog [req-9f33e658-e4d8-48f2-ae04-0c42cf4f0089 req-c9983268-cb3f-474f-9b82-29c24c025e18 service placement] Starting request: 172.16.3.11 "POST /placement/resource_providers" {{(pid=14371) __call__ /opt/stack/placement/placement/requestlog.py:38}}
Jan 02 14:04:47 jfz1r03h11 devstack@placement-api.service[14363]: DEBUG placement.wsgi_wrapper [req-9f33e658-e4d8-48f2-ae04-0c42cf4f0089 req-c9983268-cb3f-474f-9b82-29c24c025e18 service placement] Placement API returning an error response: Conflicting resource provider name: jfz1r03h11 already exists. {{(pid=14371) call_func /opt/stack/placement/placement/wsgi_wrapper.py:31}}
Jan 02 14:04:47 jfz1r03h11 devstack@placement-api.service[14363]: INFO placement.requestlog [req-9f33e658-e4d8-48f2-ae04-0c42cf4f0089 req-c9983268-cb3f-474f-9b82-29c24c025e18 service placement] 172.16.3.11 "POST /placement/resource_providers" status: 409 len: 249 microversion: 1.20
Jan 02 14:04:47 jfz1r03h11 devstack@placement-api.service[14363]: [pid: 14371|app: 0|req: 28/504] 172.16.3.11 () {68 vars in 1415 bytes} [Wed Jan  2 14:04:47 2019] POST /placement/resource_providers => generated 249 bytes in 14 msecs (HTTP/1.1 409) 6 headers in 231 bytes (2 switches on core 0)
Jan 02 14:05:49 jfz1r03h11 devstack@placement-api.service[14363]: DEBUG placement.requestlog [req-c8e54112-8098-4776-9e5e-08542283152d req-59a7fb18-3acc-48b7-a60f-f30b6c6c976c service placement] Starting request: 172.16.3.11 "GET /placement/resource_providers/ec763e10-0c86-43eb-a2e0-25e429390a15/allocations" {{(pid=14375) __call__ /opt/stack/placement/placement/requestlog.py:38}}
Jan 02 14:05:49 jfz1r03h11 devstack@placement-api.service[14363]: DEBUG placement.wsgi_wrapper [req-c8e54112-8098-4776-9e5e-08542283152d req-59a7fb18-3acc-48b7-a60f-f30b6c6c976c service placement] Placement API returning an error response: Resource provider 'ec763e10-0c86-43eb-a2e0-25e429390a15' not found: No resource provider with uuid ec763e10-0c86-43eb-a2e0-25e429390a15 found {{(pid=14375) call_func /opt/stack/placement/placement/wsgi_wrapper.py:31}}
Jan 02 14:05:49 jfz1r03h11 devstack@placement-api.service[14363]: INFO placement.requestlog [req-c8e54112-8098-4776-9e5e-08542283152d req-59a7fb18-3acc-48b7-a60f-f30b6c6c976c service placement] 172.16.3.11 "GET /placement/resource_providers/ec763e10-0c86-43eb-a2e0-25e429390a15/allocations" status: 404 len: 303 microversion: 1.0
Jan 02 14:05:49 jfz1r03h11 devstack@placement-api.service[14363]: [pid: 14375|app: 0|req: 28/505] 172.16.3.11 () {62 vars in 1465 bytes} [Wed Jan  2 14:05:49 2019] GET /placement/resource_providers/ec763e10-0c86-43eb-a2e0-25e429390a15/allocations => generated 303 bytes in 16 msecs (HTTP/1.1 404) 6 headers in 231 bytes (1 switches on core 0)
Jan 02 14:05:49 jfz1r03h11 devstack@placement-api.service[14363]: DEBUG placement.requestlog [req-c8e54112-8098-4776-9e5e-08542283152d req-d27ab9a5-c37a-4835-9331-e755137b2b2a service placement] Starting request: 172.16.3.11 "GET /placement/resource_providers?in_tree=ec763e10-0c86-43eb-a2e0-25e429390a15" {{(pid=14374) __call__ /opt/stack/placement/placement/requestlog.py:38}}
Jan 02 14:05:49 jfz1r03h11 devstack@placement-api.service[14363]: INFO placement.requestlog [req-c8e54112-8098-4776-9e5e-08542283152d req-d27ab9a5-c37a-4835-9331-e755137b2b2a service placement] 172.16.3.11 "GET /placement/resource_providers?in_tree=ec763e10-0c86-43eb-a2e0-25e429390a15" status: 200 len: 26 microversion: 1.14
Jan 02 14:05:49 jfz1r03h11 devstack@placement-api.service[14363]: [pid: 14374|app: 0|req: 30/506] 172.16.3.11 () {64 vars in 1451 bytes} [Wed Jan  2 14:05:49 2019] GET /placement/resource_providers?in_tree=ec763e10-0c86-43eb-a2e0-25e429390a15 => generated 26 bytes in 20 msecs (HTTP/1.1 200) 6 headers in 224 bytes (1 switches on core 0)
Jan 02 14:05:49 jfz1r03h11 devstack@placement-api.service[14363]: DEBUG placement.requestlog [req-c8e54112-8098-4776-9e5e-08542283152d req-2e735bd6-0e28-43f3-9dc1-1b21f6f4b090 service placement] Starting request: 172.16.3.11 "POST /placement/resource_providers" {{(pid=14385) __call__ /opt/stack/placement/placement/requestlog.py:38}}
Jan 02 14:05:49 jfz1r03h11 devstack@placement-api.service[14363]: DEBUG placement.wsgi_wrapper [req-c8e54112-8098-4776-9e5e-08542283152d req-2e735bd6-0e28-43f3-9dc1-1b21f6f4b090 service placement] Placement API returning an error response: Conflicting resource provider name: jfz1r03h11 already exists. {{(pid=14385) call_func /opt/stack/placement/placement/wsgi_wrapper.py:31}}
Jan 02 14:05:49 jfz1r03h11 devstack@placement-api.service[14363]: INFO placement.requestlog [req-c8e54112-8098-4776-9e5e-08542283152d req-2e735bd6-0e28-43f3-9dc1-1b21f6f4b090 service placement] 172.16.3.11 "POST /placement/resource_providers" status: 409 len: 249 microversion: 1.20
Jan 02 14:05:49 jfz1r03h11 devstack@placement-api.service[14363]: [pid: 14385|app: 0|req: 29/507] 172.16.3.11 () {68 vars in 1415 bytes} [Wed Jan  2 14:05:49 2019] POST /placement/resource_providers => generated 249 bytes in 14 msecs (HTTP/1.1 409) 6 headers in 231 bytes (1 switches on core 0)
Jan 02 14:06:50 jfz1r03h11 devstack@placement-api.service[14363]: DEBUG placement.requestlog [req-c3d7cfa3-112f-443a-a2b8-803634fa0b23 req-75bc5a84-318d-438f-945b-fd0b242f8587 service placement] Starting request: 172.16.3.11 "GET /placement/resource_providers/ec763e10-0c86-43eb-a2e0-25e429390a15/allocations" {{(pid=14380) __call__ /opt/stack/placement/placement/requestlog.py:38}}
Jan 02 14:06:50 jfz1r03h11 devstack@placement-api.service[14363]: DEBUG placement.wsgi_wrapper [req-c3d7cfa3-112f-443a-a2b8-803634fa0b23 req-75bc5a84-318d-438f-945b-fd0b242f8587 service placement] Placement API returning an error response: Resource provider 'ec763e10-0c86-43eb-a2e0-25e429390a15' not found: No resource provider with uuid ec763e10-0c86-43eb-a2e0-25e429390a15 found {{(pid=14380) call_func /opt/stack/placement/placement/wsgi_wrapper.py:31}}
Jan 02 14:06:50 jfz1r03h11 devstack@placement-api.service[14363]: INFO placement.requestlog [req-c3d7cfa3-112f-443a-a2b8-803634fa0b23 req-75bc5a84-318d-438f-945b-fd0b242f8587 service placement] 172.16.3.11 "GET /placement/resource_providers/ec763e10-0c86-43eb-a2e0-25e429390a15/allocations" status: 404 len: 303 microversion: 1.0
Jan 02 14:06:50 jfz1r03h11 devstack@placement-api.service[14363]: [pid: 14380|app: 0|req: 29/508] 172.16.3.11 () {62 vars in 1465 bytes} [Wed Jan  2 14:06:50 2019] GET /placement/resource_providers/ec763e10-0c86-43eb-a2e0-25e429390a15/allocations => generated 303 bytes in 15 msecs (HTTP/1.1 404) 6 headers in 231 bytes (1 switches on core 0)
Jan 02 14:06:50 jfz1r03h11 devstack@placement-api.service[14363]: DEBUG placement.requestlog [req-c3d7cfa3-112f-443a-a2b8-803634fa0b23 req-cc17ba00-6503-46ff-b19c-c66d19aeed18 service placement] Starting request: 172.16.3.11 "GET /placement/resource_providers?in_tree=ec763e10-0c86-43eb-a2e0-25e429390a15" {{(pid=14381) __call__ /opt/stack/placement/placement/requestlog.py:38}}
Jan 02 14:06:50 jfz1r03h11 devstack@placement-api.service[14363]: INFO placement.requestlog [req-c3d7cfa3-112f-443a-a2b8-803634fa0b23 req-cc17ba00-6503-46ff-b19c-c66d19aeed18 service placement] 172.16.3.11 "GET /placement/resource_providers?in_tree=ec763e10-0c86-43eb-a2e0-25e429390a15" status: 200 len: 26 microversion: 1.14
Jan 02 14:06:50 jfz1r03h11 devstack@placement-api.service[14363]: [pid: 14381|app: 0|req: 29/509] 172.16.3.11 () {64 vars in 1451 bytes} [Wed Jan  2 14:06:50 2019] GET /placement/resource_providers?in_tree=ec763e10-0c86-43eb-a2e0-25e429390a15 => generated 26 bytes in 19 msecs (HTTP/1.1 200) 6 headers in 224 bytes (1 switches on core 0)
Jan 02 14:06:50 jfz1r03h11 devstack@placement-api.service[14363]: DEBUG placement.requestlog [req-c3d7cfa3-112f-443a-a2b8-803634fa0b23 req-a7deeb54-9757-40f2-a116-100311fa1e50 service placement] Starting request: 172.16.3.11 "POST /placement/resource_providers" {{(pid=14376) __call__ /opt/stack/placement/placement/requestlog.py:38}}
Jan 02 14:06:50 jfz1r03h11 devstack@placement-api.service[14363]: DEBUG placement.wsgi_wrapper [req-c3d7cfa3-112f-443a-a2b8-803634fa0b23 req-a7deeb54-9757-40f2-a116-100311fa1e50 service placement] Placement API returning an error response: Conflicting resource provider name: jfz1r03h11 already exists. {{(pid=14376) call_func /opt/stack/placement/placement/wsgi_wrapper.py:31}}
Jan 02 14:06:50 jfz1r03h11 devstack@placement-api.service[14363]: INFO placement.requestlog [req-c3d7cfa3-112f-443a-a2b8-803634fa0b23 req-a7deeb54-9757-40f2-a116-100311fa1e50 service placement] 172.16.3.11 "POST /placement/resource_providers" status: 409 len: 249 microversion: 1.20
Jan 02 14:06:50 jfz1r03h11 devstack@placement-api.service[14363]: [pid: 14376|app: 0|req: 29/510] 172.16.3.11 () {68 vars in 1415 bytes} [Wed Jan  2 14:06:50 2019] POST /placement/resource_providers => generated 249 bytes in 15 msecs (HTTP/1.1 409) 6 headers in 231 bytes (2 switches on core 0)
Jan 02 14:07:50 jfz1r03h11 devstack@placement-api.service[14363]: DEBUG placement.requestlog [req-deb4ea88-ca56-48c1-8d16-757429029e9f req-63cc5842-40ee-4830-b3c9-ccfd2ff9ba67 service placement] Starting request: 172.16.3.11 "GET /placement/resource_providers/ec763e10-0c86-43eb-a2e0-25e429390a15/allocations" {{(pid=14369) __call__ /opt/stack/placement/placement/requestlog.py:38}}
Jan 02 14:07:50 jfz1r03h11 devstack@placement-api.service[14363]: DEBUG placement.wsgi_wrapper [req-deb4ea88-ca56-48c1-8d16-757429029e9f req-63cc5842-40ee-4830-b3c9-ccfd2ff9ba67 service placement] Placement API returning an error response: Resource provider 'ec763e10-0c86-43eb-a2e0-25e429390a15' not found: No resource provider with uuid ec763e10-0c86-43eb-a2e0-25e429390a15 found {{(pid=14369) call_func /opt/stack/placement/placement/wsgi_wrapper.py:31}}
Jan 02 14:07:50 jfz1r03h11 devstack@placement-api.service[14363]: INFO placement.requestlog [req-deb4ea88-ca56-48c1-8d16-757429029e9f req-63cc5842-40ee-4830-b3c9-ccfd2ff9ba67 service placement] 172.16.3.11 "GET /placement/resource_providers/ec763e10-0c86-43eb-a2e0-25e429390a15/allocations" status: 404 len: 303 microversion: 1.0
Jan 02 14:07:50 jfz1r03h11 devstack@placement-api.service[14363]: [pid: 14369|app: 0|req: 29/511] 172.16.3.11 () {62 vars in 1465 bytes} [Wed Jan  2 14:07:50 2019] GET /placement/resource_providers/ec763e10-0c86-43eb-a2e0-25e429390a15/allocations => generated 303 bytes in 224 msecs (HTTP/1.1 404) 6 headers in 231 bytes (1 switches on core 0)
Jan 02 14:07:50 jfz1r03h11 devstack@placement-api.service[14363]: DEBUG placement.requestlog [req-deb4ea88-ca56-48c1-8d16-757429029e9f req-58f9ea47-2e43-49a6-b320-b818127da0b1 service placement] Starting request: 172.16.3.11 "GET /placement/resource_providers?in_tree=ec763e10-0c86-43eb-a2e0-25e429390a15" {{(pid=14367) __call__ /opt/stack/placement/placement/requestlog.py:38}}
Jan 02 14:07:50 jfz1r03h11 devstack@placement-api.service[14363]: INFO placement.requestlog [req-deb4ea88-ca56-48c1-8d16-757429029e9f req-58f9ea47-2e43-49a6-b320-b818127da0b1 service placement] 172.16.3.11 "GET /placement/resource_providers?in_tree=ec763e10-0c86-43eb-a2e0-25e429390a15" status: 200 len: 26 microversion: 1.14
Jan 02 14:07:50 jfz1r03h11 devstack@placement-api.service[14363]: [pid: 14367|app: 0|req: 29/512] 172.16.3.11 () {64 vars in 1451 bytes} [Wed Jan  2 14:07:50 2019] GET /placement/resource_providers?in_tree=ec763e10-0c86-43eb-a2e0-25e429390a15 => generated 26 bytes in 22 msecs (HTTP/1.1 200) 6 headers in 224 bytes (2 switches on core 0)
Jan 02 14:07:50 jfz1r03h11 devstack@placement-api.service[14363]: DEBUG placement.requestlog [req-deb4ea88-ca56-48c1-8d16-757429029e9f req-3fea3617-943c-4ba4-b97e-ca6bafb4b133 service placement] Starting request: 172.16.3.11 "POST /placement/resource_providers" {{(pid=14370) __call__ /opt/stack/placement/placement/requestlog.py:38}}
Jan 02 14:07:50 jfz1r03h11 devstack@placement-api.service[14363]: DEBUG placement.wsgi_wrapper [req-deb4ea88-ca56-48c1-8d16-757429029e9f req-3fea3617-943c-4ba4-b97e-ca6bafb4b133 service placement] Placement API returning an error response: Conflicting resource provider name: jfz1r03h11 already exists. {{(pid=14370) call_func /opt/stack/placement/placement/wsgi_wrapper.py:31}}
Jan 02 14:07:50 jfz1r03h11 devstack@placement-api.service[14363]: INFO placement.requestlog [req-deb4ea88-ca56-48c1-8d16-757429029e9f req-3fea3617-943c-4ba4-b97e-ca6bafb4b133 service placement] 172.16.3.11 "POST /placement/resource_providers" status: 409 len: 249 microversion: 1.20
Jan 02 14:07:50 jfz1r03h11 devstack@placement-api.service[14363]: [pid: 14370|app: 0|req: 29/513] 172.16.3.11 () {68 vars in 1415 bytes} [Wed Jan  2 14:07:50 2019] POST /placement/resource_providers => generated 249 bytes in 13 msecs (HTTP/1.1 409) 6 headers in 231 bytes (2 switches on core 0)
Jan 02 14:08:51 jfz1r03h11 devstack@placement-api.service[14363]: DEBUG placement.requestlog [req-ff0a3fc7-899e-40be-8584-76605f5c19b7 req-ac24ac10-6656-4294-a194-3a7420fe5c9a service placement] Starting request: 172.16.3.11 "GET /placement/resource_providers/ec763e10-0c86-43eb-a2e0-25e429390a15/allocations" {{(pid=14379) __call__ /opt/stack/placement/placement/requestlog.py:38}}
Jan 02 14:08:51 jfz1r03h11 devstack@placement-api.service[14363]: DEBUG placement.wsgi_wrapper [req-ff0a3fc7-899e-40be-8584-76605f5c19b7 req-ac24ac10-6656-4294-a194-3a7420fe5c9a service placement] Placement API returning an error response: Resource provider 'ec763e10-0c86-43eb-a2e0-25e429390a15' not found: No resource provider with uuid ec763e10-0c86-43eb-a2e0-25e429390a15 found {{(pid=14379) call_func /opt/stack/placement/placement/wsgi_wrapper.py:31}}
Jan 02 14:08:51 jfz1r03h11 devstack@placement-api.service[14363]: INFO placement.requestlog [req-ff0a3fc7-899e-40be-8584-76605f5c19b7 req-ac24ac10-6656-4294-a194-3a7420fe5c9a service placement] 172.16.3.11 "GET /placement/resource_providers/ec763e10-0c86-43eb-a2e0-25e429390a15/allocations" status: 404 len: 303 microversion: 1.0
Jan 02 14:08:51 jfz1r03h11 devstack@placement-api.service[14363]: [pid: 14379|app: 0|req: 29/514] 172.16.3.11 () {62 vars in 1465 bytes} [Wed Jan  2 14:08:51 2019] GET /placement/resource_providers/ec763e10-0c86-43eb-a2e0-25e429390a15/allocations => generated 303 bytes in 15 msecs (HTTP/1.1 404) 6 headers in 231 bytes (2 switches on core 0)
Jan 02 14:08:51 jfz1r03h11 devstack@placement-api.service[14363]: DEBUG placement.requestlog [req-ff0a3fc7-899e-40be-8584-76605f5c19b7 req-d1ba82e5-8919-4a75-914c-223e361173ba service placement] Starting request: 172.16.3.11 "GET /placement/resource_providers?in_tree=ec763e10-0c86-43eb-a2e0-25e429390a15" {{(pid=14373) __call__ /opt/stack/placement/placement/requestlog.py:38}}
Jan 02 14:08:51 jfz1r03h11 devstack@placement-api.service[14363]: INFO placement.requestlog [req-ff0a3fc7-899e-40be-8584-76605f5c19b7 req-d1ba82e5-8919-4a75-914c-223e361173ba service placement] 172.16.3.11 "GET /placement/resource_providers?in_tree=ec763e10-0c86-43eb-a2e0-25e429390a15" status: 200 len: 26 microversion: 1.14
Jan 02 14:08:51 jfz1r03h11 devstack@placement-api.service[14363]: [pid: 14373|app: 0|req: 29/515] 172.16.3.11 () {64 vars in 1451 bytes} [Wed Jan  2 14:08:51 2019] GET /placement/resource_providers?in_tree=ec763e10-0c86-43eb-a2e0-25e429390a15 => generated 26 bytes in 19 msecs (HTTP/1.1 200) 6 headers in 224 bytes (2 switches on core 0)
Jan 02 14:08:51 jfz1r03h11 devstack@placement-api.service[14363]: DEBUG placement.requestlog [req-ff0a3fc7-899e-40be-8584-76605f5c19b7 req-a1460498-7643-4c9a-b5d3-89e790643b96 service placement] Starting request: 172.16.3.11 "POST /placement/resource_providers" {{(pid=14377) __call__ /opt/stack/placement/placement/requestlog.py:38}}
Jan 02 14:08:51 jfz1r03h11 devstack@placement-api.service[14363]: DEBUG placement.wsgi_wrapper [req-ff0a3fc7-899e-40be-8584-76605f5c19b7 req-a1460498-7643-4c9a-b5d3-89e790643b96 service placement] Placement API returning an error response: Conflicting resource provider name: jfz1r03h11 already exists. {{(pid=14377) call_func /opt/stack/placement/placement/wsgi_wrapper.py:31}}
Jan 02 14:08:51 jfz1r03h11 devstack@placement-api.service[14363]: INFO placement.requestlog [req-ff0a3fc7-899e-40be-8584-76605f5c19b7 req-a1460498-7643-4c9a-b5d3-89e790643b96 service placement] 172.16.3.11 "POST /placement/resource_providers" status: 409 len: 249 microversion: 1.20
Jan 02 14:08:51 jfz1r03h11 devstack@placement-api.service[14363]: [pid: 14377|app: 0|req: 29/516] 172.16.3.11 () {68 vars in 1415 bytes} [Wed Jan  2 14:08:51 2019] POST /placement/resource_providers => generated 249 bytes in 18 msecs (HTTP/1.1 409) 6 headers in 231 bytes (1 switches on core 0)
Jan 02 14:09:53 jfz1r03h11 devstack@placement-api.service[14363]: DEBUG placement.requestlog [req-773bdffe-c075-451d-9b71-40038ab9160f req-aa2c6f36-96c0-4789-b3c3-e46e78e36fc4 service placement] Starting request: 172.16.3.11 "GET /placement/resource_providers/ec763e10-0c86-43eb-a2e0-25e429390a15/allocations" {{(pid=14383) __call__ /opt/stack/placement/placement/requestlog.py:38}}
Jan 02 14:09:53 jfz1r03h11 devstack@placement-api.service[14363]: DEBUG placement.wsgi_wrapper [req-773bdffe-c075-451d-9b71-40038ab9160f req-aa2c6f36-96c0-4789-b3c3-e46e78e36fc4 service placement] Placement API returning an error response: Resource provider 'ec763e10-0c86-43eb-a2e0-25e429390a15' not found: No resource provider with uuid ec763e10-0c86-43eb-a2e0-25e429390a15 found {{(pid=14383) call_func /opt/stack/placement/placement/wsgi_wrapper.py:31}}
Jan 02 14:09:53 jfz1r03h11 devstack@placement-api.service[14363]: INFO placement.requestlog [req-773bdffe-c075-451d-9b71-40038ab9160f req-aa2c6f36-96c0-4789-b3c3-e46e78e36fc4 service placement] 172.16.3.11 "GET /placement/resource_providers/ec763e10-0c86-43eb-a2e0-25e429390a15/allocations" status: 404 len: 303 microversion: 1.0
Jan 02 14:09:53 jfz1r03h11 devstack@placement-api.service[14363]: [pid: 14383|app: 0|req: 29/517] 172.16.3.11 () {62 vars in 1465 bytes} [Wed Jan  2 14:09:53 2019] GET /placement/resource_providers/ec763e10-0c86-43eb-a2e0-25e429390a15/allocations => generated 303 bytes in 12 msecs (HTTP/1.1 404) 6 headers in 231 bytes (2 switches on core 0)
Jan 02 14:09:53 jfz1r03h11 devstack@placement-api.service[14363]: DEBUG placement.requestlog [req-773bdffe-c075-451d-9b71-40038ab9160f req-a4812707-9c28-46ea-bbdd-718d19b1febc service placement] Starting request: 172.16.3.11 "GET /placement/resource_providers?in_tree=ec763e10-0c86-43eb-a2e0-25e429390a15" {{(pid=14368) __call__ /opt/stack/placement/placement/requestlog.py:38}}
Jan 02 14:09:53 jfz1r03h11 devstack@placement-api.service[14363]: INFO placement.requestlog [req-773bdffe-c075-451d-9b71-40038ab9160f req-a4812707-9c28-46ea-bbdd-718d19b1febc service placement] 172.16.3.11 "GET /placement/resource_providers?in_tree=ec763e10-0c86-43eb-a2e0-25e429390a15" status: 200 len: 26 microversion: 1.14
Jan 02 14:09:53 jfz1r03h11 devstack@placement-api.service[14363]: [pid: 14368|app: 0|req: 29/518] 172.16.3.11 () {64 vars in 1451 bytes} [Wed Jan  2 14:09:53 2019] GET /placement/resource_providers?in_tree=ec763e10-0c86-43eb-a2e0-25e429390a15 => generated 26 bytes in 18 msecs (HTTP/1.1 200) 6 headers in 224 bytes (1 switches on core 0)
Jan 02 14:09:53 jfz1r03h11 devstack@placement-api.service[14363]: DEBUG placement.requestlog [req-773bdffe-c075-451d-9b71-40038ab9160f req-df30dae9-ef53-4e8e-9e35-8d4b67074557 service placement] Starting request: 172.16.3.11 "POST /placement/resource_providers" {{(pid=14382) __call__ /opt/stack/placement/placement/requestlog.py:38}}
Jan 02 14:09:53 jfz1r03h11 devstack@placement-api.service[14363]: DEBUG placement.wsgi_wrapper [req-773bdffe-c075-451d-9b71-40038ab9160f req-df30dae9-ef53-4e8e-9e35-8d4b67074557 service placement] Placement API returning an error response: Conflicting resource provider name: jfz1r03h11 already exists. {{(pid=14382) call_func /opt/stack/placement/placement/wsgi_wrapper.py:31}}
Jan 02 14:09:53 jfz1r03h11 devstack@placement-api.service[14363]: INFO placement.requestlog [req-773bdffe-c075-451d-9b71-40038ab9160f req-df30dae9-ef53-4e8e-9e35-8d4b67074557 service placement] 172.16.3.11 "POST /placement/resource_providers" status: 409 len: 249 microversion: 1.20
Jan 02 14:09:53 jfz1r03h11 devstack@placement-api.service[14363]: [pid: 14382|app: 0|req: 29/519] 172.16.3.11 () {68 vars in 1415 bytes} [Wed Jan  2 14:09:53 2019] POST /placement/resource_providers => generated 249 bytes in 20 msecs (HTTP/1.1 409) 6 headers in 231 bytes (2 switches on core 0)
Jan 02 14:10:55 jfz1r03h11 devstack@placement-api.service[14363]: DEBUG placement.requestlog [req-d69c07ae-5862-4596-ab2f-4946d6999593 req-490241b7-2fa0-4526-96c6-5862b7a0fa92 service placement] Starting request: 172.16.3.11 "GET /placement/resource_providers/ec763e10-0c86-43eb-a2e0-25e429390a15/allocations" {{(pid=14384) __call__ /opt/stack/placement/placement/requestlog.py:38}}
Jan 02 14:10:55 jfz1r03h11 devstack@placement-api.service[14363]: DEBUG placement.wsgi_wrapper [req-d69c07ae-5862-4596-ab2f-4946d6999593 req-490241b7-2fa0-4526-96c6-5862b7a0fa92 service placement] Placement API returning an error response: Resource provider 'ec763e10-0c86-43eb-a2e0-25e429390a15' not found: No resource provider with uuid ec763e10-0c86-43eb-a2e0-25e429390a15 found {{(pid=14384) call_func /opt/stack/placement/placement/wsgi_wrapper.py:31}}
Jan 02 14:10:55 jfz1r03h11 devstack@placement-api.service[14363]: INFO placement.requestlog [req-d69c07ae-5862-4596-ab2f-4946d6999593 req-490241b7-2fa0-4526-96c6-5862b7a0fa92 service placement] 172.16.3.11 "GET /placement/resource_providers/ec763e10-0c86-43eb-a2e0-25e429390a15/allocations" status: 404 len: 303 microversion: 1.0
Jan 02 14:10:55 jfz1r03h11 devstack@placement-api.service[14363]: [pid: 14384|app: 0|req: 29/520] 172.16.3.11 () {62 vars in 1465 bytes} [Wed Jan  2 14:10:55 2019] GET /placement/resource_providers/ec763e10-0c86-43eb-a2e0-25e429390a15/allocations => generated 303 bytes in 15 msecs (HTTP/1.1 404) 6 headers in 231 bytes (2 switches on core 0)
Jan 02 14:10:55 jfz1r03h11 devstack@placement-api.service[14363]: DEBUG placement.requestlog [req-d69c07ae-5862-4596-ab2f-4946d6999593 req-e5383d0c-fc4a-4f08-af10-f16f48faa692 service placement] Starting request: 172.16.3.11 "GET /placement/resource_providers?in_tree=ec763e10-0c86-43eb-a2e0-25e429390a15" {{(pid=14378) __call__ /opt/stack/placement/placement/requestlog.py:38}}
Jan 02 14:10:55 jfz1r03h11 devstack@placement-api.service[14363]: INFO placement.requestlog [req-d69c07ae-5862-4596-ab2f-4946d6999593 req-e5383d0c-fc4a-4f08-af10-f16f48faa692 service placement] 172.16.3.11 "GET /placement/resource_providers?in_tree=ec763e10-0c86-43eb-a2e0-25e429390a15" status: 200 len: 26 microversion: 1.14
Jan 02 14:10:55 jfz1r03h11 devstack@placement-api.service[14363]: [pid: 14378|app: 0|req: 29/521] 172.16.3.11 () {64 vars in 1451 bytes} [Wed Jan  2 14:10:55 2019] GET /placement/resource_providers?in_tree=ec763e10-0c86-43eb-a2e0-25e429390a15 => generated 26 bytes in 17 msecs (HTTP/1.1 200) 6 headers in 224 bytes (1 switches on core 0)
Jan 02 14:10:55 jfz1r03h11 devstack@placement-api.service[14363]: DEBUG placement.requestlog [req-d69c07ae-5862-4596-ab2f-4946d6999593 req-3c06ab99-ceda-489c-9863-93636415bda8 service placement] Starting request: 172.16.3.11 "POST /placement/resource_providers" {{(pid=14371) __call__ /opt/stack/placement/placement/requestlog.py:38}}
Jan 02 14:10:55 jfz1r03h11 devstack@placement-api.service[14363]: DEBUG placement.wsgi_wrapper [req-d69c07ae-5862-4596-ab2f-4946d6999593 req-3c06ab99-ceda-489c-9863-93636415bda8 service placement] Placement API returning an error response: Conflicting resource provider name: jfz1r03h11 already exists. {{(pid=14371) call_func /opt/stack/placement/placement/wsgi_wrapper.py:31}}
Jan 02 14:10:55 jfz1r03h11 devstack@placement-api.service[14363]: INFO placement.requestlog [req-d69c07ae-5862-4596-ab2f-4946d6999593 req-3c06ab99-ceda-489c-9863-93636415bda8 service placement] 172.16.3.11 "POST /placement/resource_providers" status: 409 len: 249 microversion: 1.20
Jan 02 14:10:55 jfz1r03h11 devstack@placement-api.service[14363]: [pid: 14371|app: 0|req: 29/522] 172.16.3.11 () {68 vars in 1415 bytes} [Wed Jan  2 14:10:55 2019] POST /placement/resource_providers => generated 249 bytes in 15 msecs (HTTP/1.1 409) 6 headers in 231 bytes (1 switches on core 0)
Jan 02 14:11:55 jfz1r03h11 devstack@placement-api.service[14363]: DEBUG placement.requestlog [req-ff3c3199-2537-4e38-ae92-3e759116d8f3 req-e9945923-444d-45a5-9f95-f7f83820a365 service placement] Starting request: 172.16.3.11 "GET /placement/resource_providers/ec763e10-0c86-43eb-a2e0-25e429390a15/allocations" {{(pid=14375) __call__ /opt/stack/placement/placement/requestlog.py:38}}
Jan 02 14:11:55 jfz1r03h11 devstack@placement-api.service[14363]: DEBUG placement.wsgi_wrapper [req-ff3c3199-2537-4e38-ae92-3e759116d8f3 req-e9945923-444d-45a5-9f95-f7f83820a365 service placement] Placement API returning an error response: Resource provider 'ec763e10-0c86-43eb-a2e0-25e429390a15' not found: No resource provider with uuid ec763e10-0c86-43eb-a2e0-25e429390a15 found {{(pid=14375) call_func /opt/stack/placement/placement/wsgi_wrapper.py:31}}
Jan 02 14:11:55 jfz1r03h11 devstack@placement-api.service[14363]: INFO placement.requestlog [req-ff3c3199-2537-4e38-ae92-3e759116d8f3 req-e9945923-444d-45a5-9f95-f7f83820a365 service placement] 172.16.3.11 "GET /placement/resource_providers/ec763e10-0c86-43eb-a2e0-25e429390a15/allocations" status: 404 len: 303 microversion: 1.0
Jan 02 14:11:55 jfz1r03h11 devstack@placement-api.service[14363]: [pid: 14375|app: 0|req: 29/523] 172.16.3.11 () {62 vars in 1465 bytes} [Wed Jan  2 14:11:55 2019] GET /placement/resource_providers/ec763e10-0c86-43eb-a2e0-25e429390a15/allocations => generated 303 bytes in 13 msecs (HTTP/1.1 404) 6 headers in 231 bytes (2 switches on core 0)
Jan 02 14:11:55 jfz1r03h11 devstack@placement-api.service[14363]: DEBUG placement.requestlog [req-ff3c3199-2537-4e38-ae92-3e759116d8f3 req-cccd11f8-eb95-4b04-bd0b-faa78dd5b70e service placement] Starting request: 172.16.3.11 "GET /placement/resource_providers?in_tree=ec763e10-0c86-43eb-a2e0-25e429390a15" {{(pid=14374) __call__ /opt/stack/placement/placement/requestlog.py:38}}
Jan 02 14:11:55 jfz1r03h11 devstack@placement-api.service[14363]: INFO placement.requestlog [req-ff3c3199-2537-4e38-ae92-3e759116d8f3 req-cccd11f8-eb95-4b04-bd0b-faa78dd5b70e service placement] 172.16.3.11 "GET /placement/resource_providers?in_tree=ec763e10-0c86-43eb-a2e0-25e429390a15" status: 200 len: 26 microversion: 1.14
Jan 02 14:11:55 jfz1r03h11 devstack@placement-api.service[14363]: [pid: 14374|app: 0|req: 31/524] 172.16.3.11 () {64 vars in 1451 bytes} [Wed Jan  2 14:11:55 2019] GET /placement/resource_providers?in_tree=ec763e10-0c86-43eb-a2e0-25e429390a15 => generated 26 bytes in 17 msecs (HTTP/1.1 200) 6 headers in 224 bytes (2 switches on core 0)
Jan 02 14:11:55 jfz1r03h11 devstack@placement-api.service[14363]: DEBUG placement.requestlog [req-ff3c3199-2537-4e38-ae92-3e759116d8f3 req-cf3121d4-83a1-42ce-bac1-32ada1348f41 service placement] Starting request: 172.16.3.11 "POST /placement/resource_providers" {{(pid=14385) __call__ /opt/stack/placement/placement/requestlog.py:38}}
Jan 02 14:11:55 jfz1r03h11 devstack@placement-api.service[14363]: DEBUG placement.wsgi_wrapper [req-ff3c3199-2537-4e38-ae92-3e759116d8f3 req-cf3121d4-83a1-42ce-bac1-32ada1348f41 service placement] Placement API returning an error response: Conflicting resource provider name: jfz1r03h11 already exists. {{(pid=14385) call_func /opt/stack/placement/placement/wsgi_wrapper.py:31}}
Jan 02 14:11:55 jfz1r03h11 devstack@placement-api.service[14363]: INFO placement.requestlog [req-ff3c3199-2537-4e38-ae92-3e759116d8f3 req-cf3121d4-83a1-42ce-bac1-32ada1348f41 service placement] 172.16.3.11 "POST /placement/resource_providers" status: 409 len: 249 microversion: 1.20
Jan 02 14:11:55 jfz1r03h11 devstack@placement-api.service[14363]: [pid: 14385|app: 0|req: 30/525] 172.16.3.11 () {68 vars in 1415 bytes} [Wed Jan  2 14:11:55 2019] POST /placement/resource_providers => generated 249 bytes in 13 msecs (HTTP/1.1 409) 6 headers in 231 bytes (1 switches on core 0)
Jan 02 14:12:57 jfz1r03h11 devstack@placement-api.service[14363]: DEBUG placement.requestlog [req-608c0b54-34e5-470a-b0cc-6c08678f2f4e req-f09bf64f-c42a-4354-bb36-e0bfebc74699 service placement] Starting request: 172.16.3.11 "GET /placement/resource_providers/ec763e10-0c86-43eb-a2e0-25e429390a15/allocations" {{(pid=14380) __call__ /opt/stack/placement/placement/requestlog.py:38}}
Jan 02 14:12:57 jfz1r03h11 devstack@placement-api.service[14363]: DEBUG placement.wsgi_wrapper [req-608c0b54-34e5-470a-b0cc-6c08678f2f4e req-f09bf64f-c42a-4354-bb36-e0bfebc74699 service placement] Placement API returning an error response: Resource provider 'ec763e10-0c86-43eb-a2e0-25e429390a15' not found: No resource provider with uuid ec763e10-0c86-43eb-a2e0-25e429390a15 found {{(pid=14380) call_func /opt/stack/placement/placement/wsgi_wrapper.py:31}}
Jan 02 14:12:57 jfz1r03h11 devstack@placement-api.service[14363]: INFO placement.requestlog [req-608c0b54-34e5-470a-b0cc-6c08678f2f4e req-f09bf64f-c42a-4354-bb36-e0bfebc74699 service placement] 172.16.3.11 "GET /placement/resource_providers/ec763e10-0c86-43eb-a2e0-25e429390a15/allocations" status: 404 len: 303 microversion: 1.0
Jan 02 14:12:57 jfz1r03h11 devstack@placement-api.service[14363]: [pid: 14380|app: 0|req: 30/526] 172.16.3.11 () {62 vars in 1465 bytes} [Wed Jan  2 14:12:57 2019] GET /placement/resource_providers/ec763e10-0c86-43eb-a2e0-25e429390a15/allocations => generated 303 bytes in 185 msecs (HTTP/1.1 404) 6 headers in 231 bytes (1 switches on core 0)
Jan 02 14:12:57 jfz1r03h11 devstack@placement-api.service[14363]: DEBUG placement.requestlog [req-608c0b54-34e5-470a-b0cc-6c08678f2f4e req-62c27c4d-7f70-4ce6-9500-921768c545f8 service placement] Starting request: 172.16.3.11 "GET /placement/resource_providers?in_tree=ec763e10-0c86-43eb-a2e0-25e429390a15" {{(pid=14381) __call__ /opt/stack/placement/placement/requestlog.py:38}}
Jan 02 14:12:57 jfz1r03h11 devstack@placement-api.service[14363]: INFO placement.requestlog [req-608c0b54-34e5-470a-b0cc-6c08678f2f4e req-62c27c4d-7f70-4ce6-9500-921768c545f8 service placement] 172.16.3.11 "GET /placement/resource_providers?in_tree=ec763e10-0c86-43eb-a2e0-25e429390a15" status: 200 len: 26 microversion: 1.14
Jan 02 14:12:57 jfz1r03h11 devstack@placement-api.service[14363]: [pid: 14381|app: 0|req: 30/527] 172.16.3.11 () {64 vars in 1451 bytes} [Wed Jan  2 14:12:57 2019] GET /placement/resource_providers?in_tree=ec763e10-0c86-43eb-a2e0-25e429390a15 => generated 26 bytes in 11 msecs (HTTP/1.1 200) 6 headers in 224 bytes (2 switches on core 0)
Jan 02 14:12:57 jfz1r03h11 devstack@placement-api.service[14363]: DEBUG placement.requestlog [req-608c0b54-34e5-470a-b0cc-6c08678f2f4e req-2da5d796-8f24-4831-839b-e358713e9185 service placement] Starting request: 172.16.3.11 "POST /placement/resource_providers" {{(pid=14376) __call__ /opt/stack/placement/placement/requestlog.py:38}}
Jan 02 14:12:57 jfz1r03h11 devstack@placement-api.service[14363]: DEBUG placement.wsgi_wrapper [req-608c0b54-34e5-470a-b0cc-6c08678f2f4e req-2da5d796-8f24-4831-839b-e358713e9185 service placement] Placement API returning an error response: Conflicting resource provider name: jfz1r03h11 already exists. {{(pid=14376) call_func /opt/stack/placement/placement/wsgi_wrapper.py:31}}
Jan 02 14:12:57 jfz1r03h11 devstack@placement-api.service[14363]: INFO placement.requestlog [req-608c0b54-34e5-470a-b0cc-6c08678f2f4e req-2da5d796-8f24-4831-839b-e358713e9185 service placement] 172.16.3.11 "POST /placement/resource_providers" status: 409 len: 249 microversion: 1.20
Jan 02 14:12:57 jfz1r03h11 devstack@placement-api.service[14363]: [pid: 14376|app: 0|req: 30/528] 172.16.3.11 () {68 vars in 1415 bytes} [Wed Jan  2 14:12:57 2019] POST /placement/resource_providers => generated 249 bytes in 13 msecs (HTTP/1.1 409) 6 headers in 231 bytes (1 switches on core 0)
Jan 02 14:13:59 jfz1r03h11 devstack@placement-api.service[14363]: DEBUG placement.requestlog [req-10ec9ad9-11dd-402d-bcf8-3c2e30df7026 req-78d6002b-ce2a-42fd-99bb-6bcd948547c0 service placement] Starting request: 172.16.3.11 "GET /placement/resource_providers/ec763e10-0c86-43eb-a2e0-25e429390a15/allocations" {{(pid=14369) __call__ /opt/stack/placement/placement/requestlog.py:38}}
Jan 02 14:13:59 jfz1r03h11 devstack@placement-api.service[14363]: ERROR oslo_db.sqlalchemy.engines [req-10ec9ad9-11dd-402d-bcf8-3c2e30df7026 req-78d6002b-ce2a-42fd-99bb-6bcd948547c0 service placement] Database connection was found disconnected; reconnecting: DBConnectionError: (pymysql.err.OperationalError) (2013, 'Lost connection to MySQL server during query') [SQL: u'SELECT 1'] (Background on this error at: http://sqlalche.me/e/e3q8)
Jan 02 14:13:59 jfz1r03h11 devstack@placement-api.service[14363]: ERROR oslo_db.sqlalchemy.engines Traceback (most recent call last):
Jan 02 14:13:59 jfz1r03h11 devstack@placement-api.service[14363]: ERROR oslo_db.sqlalchemy.engines   File "/usr/local/lib/python2.7/dist-packages/oslo_db/sqlalchemy/engines.py", line 73, in _connect_ping_listener
Jan 02 14:13:59 jfz1r03h11 devstack@placement-api.service[14363]: ERROR oslo_db.sqlalchemy.engines     connection.scalar(select([1]))
Jan 02 14:13:59 jfz1r03h11 devstack@placement-api.service[14363]: ERROR oslo_db.sqlalchemy.engines   File "/usr/local/lib/python2.7/dist-packages/sqlalchemy/engine/base.py", line 880, in scalar
Jan 02 14:13:59 jfz1r03h11 devstack@placement-api.service[14363]: ERROR oslo_db.sqlalchemy.engines     return self.execute(object, *multiparams, **params).scalar()
Jan 02 14:13:59 jfz1r03h11 devstack@placement-api.service[14363]: ERROR oslo_db.sqlalchemy.engines   File "/usr/local/lib/python2.7/dist-packages/sqlalchemy/engine/base.py", line 948, in execute
Jan 02 14:13:59 jfz1r03h11 devstack@placement-api.service[14363]: ERROR oslo_db.sqlalchemy.engines     return meth(self, multiparams, params)
Jan 02 14:13:59 jfz1r03h11 devstack@placement-api.service[14363]: ERROR oslo_db.sqlalchemy.engines   File "/usr/local/lib/python2.7/dist-packages/sqlalchemy/sql/elements.py", line 269, in _execute_on_connection
Jan 02 14:13:59 jfz1r03h11 devstack@placement-api.service[14363]: ERROR oslo_db.sqlalchemy.engines     return connection._execute_clauseelement(self, multiparams, params)
Jan 02 14:13:59 jfz1r03h11 devstack@placement-api.service[14363]: ERROR oslo_db.sqlalchemy.engines   File "/usr/local/lib/python2.7/dist-packages/sqlalchemy/engine/base.py", line 1060, in _execute_clauseelement
Jan 02 14:13:59 jfz1r03h11 devstack@placement-api.service[14363]: ERROR oslo_db.sqlalchemy.engines     compiled_sql, distilled_params
Jan 02 14:13:59 jfz1r03h11 devstack@placement-api.service[14363]: ERROR oslo_db.sqlalchemy.engines   File "/usr/local/lib/python2.7/dist-packages/sqlalchemy/engine/base.py", line 1200, in _execute_context
Jan 02 14:13:59 jfz1r03h11 devstack@placement-api.service[14363]: ERROR oslo_db.sqlalchemy.engines     context)
Jan 02 14:13:59 jfz1r03h11 devstack@placement-api.service[14363]: ERROR oslo_db.sqlalchemy.engines   File "/usr/local/lib/python2.7/dist-packages/sqlalchemy/engine/base.py", line 1409, in _handle_dbapi_exception
Jan 02 14:13:59 jfz1r03h11 devstack@placement-api.service[14363]: ERROR oslo_db.sqlalchemy.engines     util.raise_from_cause(newraise, exc_info)
Jan 02 14:13:59 jfz1r03h11 devstack@placement-api.service[14363]: ERROR oslo_db.sqlalchemy.engines   File "/usr/local/lib/python2.7/dist-packages/sqlalchemy/util/compat.py", line 265, in raise_from_cause
Jan 02 14:13:59 jfz1r03h11 devstack@placement-api.service[14363]: ERROR oslo_db.sqlalchemy.engines     reraise(type(exception), exception, tb=exc_tb, cause=cause)
Jan 02 14:13:59 jfz1r03h11 devstack@placement-api.service[14363]: ERROR oslo_db.sqlalchemy.engines   File "/usr/local/lib/python2.7/dist-packages/sqlalchemy/engine/base.py", line 1193, in _execute_context
Jan 02 14:13:59 jfz1r03h11 devstack@placement-api.service[14363]: ERROR oslo_db.sqlalchemy.engines     context)
Jan 02 14:13:59 jfz1r03h11 devstack@placement-api.service[14363]: ERROR oslo_db.sqlalchemy.engines   File "/usr/local/lib/python2.7/dist-packages/sqlalchemy/engine/default.py", line 509, in do_execute
Jan 02 14:13:59 jfz1r03h11 devstack@placement-api.service[14363]: ERROR oslo_db.sqlalchemy.engines     cursor.execute(statement, parameters)
Jan 02 14:13:59 jfz1r03h11 devstack@placement-api.service[14363]: ERROR oslo_db.sqlalchemy.engines   File "/usr/local/lib/python2.7/dist-packages/pymysql/cursors.py", line 170, in execute
Jan 02 14:13:59 jfz1r03h11 devstack@placement-api.service[14363]: ERROR oslo_db.sqlalchemy.engines     result = self._query(query)
Jan 02 14:13:59 jfz1r03h11 devstack@placement-api.service[14363]: ERROR oslo_db.sqlalchemy.engines   File "/usr/local/lib/python2.7/dist-packages/pymysql/cursors.py", line 328, in _query
Jan 02 14:13:59 jfz1r03h11 devstack@placement-api.service[14363]: ERROR oslo_db.sqlalchemy.engines     conn.query(q)
Jan 02 14:13:59 jfz1r03h11 devstack@placement-api.service[14363]: ERROR oslo_db.sqlalchemy.engines   File "/usr/local/lib/python2.7/dist-packages/pymysql/connections.py", line 517, in query
Jan 02 14:13:59 jfz1r03h11 devstack@placement-api.service[14363]: ERROR oslo_db.sqlalchemy.engines     self._affected_rows = self._read_query_result(unbuffered=unbuffered)
Jan 02 14:13:59 jfz1r03h11 devstack@placement-api.service[14363]: ERROR oslo_db.sqlalchemy.engines   File "/usr/local/lib/python2.7/dist-packages/pymysql/connections.py", line 732, in _read_query_result
Jan 02 14:13:59 jfz1r03h11 devstack@placement-api.service[14363]: ERROR oslo_db.sqlalchemy.engines     result.read()
Jan 02 14:13:59 jfz1r03h11 devstack@placement-api.service[14363]: ERROR oslo_db.sqlalchemy.engines   File "/usr/local/lib/python2.7/dist-packages/pymysql/connections.py", line 1075, in read
Jan 02 14:13:59 jfz1r03h11 devstack@placement-api.service[14363]: ERROR oslo_db.sqlalchemy.engines     first_packet = self.connection._read_packet()
Jan 02 14:13:59 jfz1r03h11 devstack@placement-api.service[14363]: ERROR oslo_db.sqlalchemy.engines   File "/usr/local/lib/python2.7/dist-packages/pymysql/connections.py", line 657, in _read_packet
Jan 02 14:13:59 jfz1r03h11 devstack@placement-api.service[14363]: ERROR oslo_db.sqlalchemy.engines     packet_header = self._read_bytes(4)
Jan 02 14:13:59 jfz1r03h11 devstack@placement-api.service[14363]: ERROR oslo_db.sqlalchemy.engines   File "/usr/local/lib/python2.7/dist-packages/pymysql/connections.py", line 707, in _read_bytes
Jan 02 14:13:59 jfz1r03h11 devstack@placement-api.service[14363]: ERROR oslo_db.sqlalchemy.engines     CR.CR_SERVER_LOST, "Lost connection to MySQL server during query")
Jan 02 14:13:59 jfz1r03h11 devstack@placement-api.service[14363]: ERROR oslo_db.sqlalchemy.engines DBConnectionError: (pymysql.err.OperationalError) (2013, 'Lost connection to MySQL server during query') [SQL: u'SELECT 1'] (Background on this error at: http://sqlalche.me/e/e3q8)
Jan 02 14:13:59 jfz1r03h11 devstack@placement-api.service[14363]: ERROR oslo_db.sqlalchemy.engines 
Jan 02 14:13:59 jfz1r03h11 devstack@placement-api.service[14363]: DEBUG placement.wsgi_wrapper [req-10ec9ad9-11dd-402d-bcf8-3c2e30df7026 req-78d6002b-ce2a-42fd-99bb-6bcd948547c0 service placement] Placement API returning an error response: Resource provider 'ec763e10-0c86-43eb-a2e0-25e429390a15' not found: No resource provider with uuid ec763e10-0c86-43eb-a2e0-25e429390a15 found {{(pid=14369) call_func /opt/stack/placement/placement/wsgi_wrapper.py:31}}
Jan 02 14:13:59 jfz1r03h11 devstack@placement-api.service[14363]: INFO placement.requestlog [req-10ec9ad9-11dd-402d-bcf8-3c2e30df7026 req-78d6002b-ce2a-42fd-99bb-6bcd948547c0 service placement] 172.16.3.11 "GET /placement/resource_providers/ec763e10-0c86-43eb-a2e0-25e429390a15/allocations" status: 404 len: 303 microversion: 1.0
Jan 02 14:13:59 jfz1r03h11 devstack@placement-api.service[14363]: [pid: 14369|app: 0|req: 30/529] 172.16.3.11 () {62 vars in 1465 bytes} [Wed Jan  2 14:13:59 2019] GET /placement/resource_providers/ec763e10-0c86-43eb-a2e0-25e429390a15/allocations => generated 303 bytes in 23 msecs (HTTP/1.1 404) 6 headers in 231 bytes (2 switches on core 0)
Jan 02 14:13:59 jfz1r03h11 devstack@placement-api.service[14363]: DEBUG placement.requestlog [req-10ec9ad9-11dd-402d-bcf8-3c2e30df7026 req-7ebda97b-4cdb-40aa-a9fb-7a5f84e22799 service placement] Starting request: 172.16.3.11 "GET /placement/resource_providers?in_tree=ec763e10-0c86-43eb-a2e0-25e429390a15" {{(pid=14367) __call__ /opt/stack/placement/placement/requestlog.py:38}}
Jan 02 14:13:59 jfz1r03h11 devstack@placement-api.service[14363]: ERROR oslo_db.sqlalchemy.engines [req-10ec9ad9-11dd-402d-bcf8-3c2e30df7026 req-7ebda97b-4cdb-40aa-a9fb-7a5f84e22799 service placement] Database connection was found disconnected; reconnecting: DBConnectionError: (pymysql.err.OperationalError) (2013, 'Lost connection to MySQL server during query') [SQL: u'SELECT 1'] (Background on this error at: http://sqlalche.me/e/e3q8)
Jan 02 14:13:59 jfz1r03h11 devstack@placement-api.service[14363]: ERROR oslo_db.sqlalchemy.engines Traceback (most recent call last):
Jan 02 14:13:59 jfz1r03h11 devstack@placement-api.service[14363]: ERROR oslo_db.sqlalchemy.engines   File "/usr/local/lib/python2.7/dist-packages/oslo_db/sqlalchemy/engines.py", line 73, in _connect_ping_listener
Jan 02 14:13:59 jfz1r03h11 devstack@placement-api.service[14363]: ERROR oslo_db.sqlalchemy.engines     connection.scalar(select([1]))
Jan 02 14:13:59 jfz1r03h11 devstack@placement-api.service[14363]: ERROR oslo_db.sqlalchemy.engines   File "/usr/local/lib/python2.7/dist-packages/sqlalchemy/engine/base.py", line 880, in scalar
Jan 02 14:13:59 jfz1r03h11 devstack@placement-api.service[14363]: ERROR oslo_db.sqlalchemy.engines     return self.execute(object, *multiparams, **params).scalar()
Jan 02 14:13:59 jfz1r03h11 devstack@placement-api.service[14363]: ERROR oslo_db.sqlalchemy.engines   File "/usr/local/lib/python2.7/dist-packages/sqlalchemy/engine/base.py", line 948, in execute
Jan 02 14:13:59 jfz1r03h11 devstack@placement-api.service[14363]: ERROR oslo_db.sqlalchemy.engines     return meth(self, multiparams, params)
Jan 02 14:13:59 jfz1r03h11 devstack@placement-api.service[14363]: ERROR oslo_db.sqlalchemy.engines   File "/usr/local/lib/python2.7/dist-packages/sqlalchemy/sql/elements.py", line 269, in _execute_on_connection
Jan 02 14:13:59 jfz1r03h11 devstack@placement-api.service[14363]: ERROR oslo_db.sqlalchemy.engines     return connection._execute_clauseelement(self, multiparams, params)
Jan 02 14:13:59 jfz1r03h11 devstack@placement-api.service[14363]: ERROR oslo_db.sqlalchemy.engines   File "/usr/local/lib/python2.7/dist-packages/sqlalchemy/engine/base.py", line 1060, in _execute_clauseelement
Jan 02 14:13:59 jfz1r03h11 devstack@placement-api.service[14363]: ERROR oslo_db.sqlalchemy.engines     compiled_sql, distilled_params
Jan 02 14:13:59 jfz1r03h11 devstack@placement-api.service[14363]: ERROR oslo_db.sqlalchemy.engines   File "/usr/local/lib/python2.7/dist-packages/sqlalchemy/engine/base.py", line 1200, in _execute_context
Jan 02 14:13:59 jfz1r03h11 devstack@placement-api.service[14363]: ERROR oslo_db.sqlalchemy.engines     context)
Jan 02 14:13:59 jfz1r03h11 devstack@placement-api.service[14363]: ERROR oslo_db.sqlalchemy.engines   File "/usr/local/lib/python2.7/dist-packages/sqlalchemy/engine/base.py", line 1409, in _handle_dbapi_exception
Jan 02 14:13:59 jfz1r03h11 devstack@placement-api.service[14363]: ERROR oslo_db.sqlalchemy.engines     util.raise_from_cause(newraise, exc_info)
Jan 02 14:13:59 jfz1r03h11 devstack@placement-api.service[14363]: ERROR oslo_db.sqlalchemy.engines   File "/usr/local/lib/python2.7/dist-packages/sqlalchemy/util/compat.py", line 265, in raise_from_cause
Jan 02 14:13:59 jfz1r03h11 devstack@placement-api.service[14363]: ERROR oslo_db.sqlalchemy.engines     reraise(type(exception), exception, tb=exc_tb, cause=cause)
Jan 02 14:13:59 jfz1r03h11 devstack@placement-api.service[14363]: ERROR oslo_db.sqlalchemy.engines   File "/usr/local/lib/python2.7/dist-packages/sqlalchemy/engine/base.py", line 1193, in _execute_context
Jan 02 14:13:59 jfz1r03h11 devstack@placement-api.service[14363]: ERROR oslo_db.sqlalchemy.engines     context)
Jan 02 14:13:59 jfz1r03h11 devstack@placement-api.service[14363]: ERROR oslo_db.sqlalchemy.engines   File "/usr/local/lib/python2.7/dist-packages/sqlalchemy/engine/default.py", line 509, in do_execute
Jan 02 14:13:59 jfz1r03h11 devstack@placement-api.service[14363]: ERROR oslo_db.sqlalchemy.engines     cursor.execute(statement, parameters)
Jan 02 14:13:59 jfz1r03h11 devstack@placement-api.service[14363]: ERROR oslo_db.sqlalchemy.engines   File "/usr/local/lib/python2.7/dist-packages/pymysql/cursors.py", line 170, in execute
Jan 02 14:13:59 jfz1r03h11 devstack@placement-api.service[14363]: ERROR oslo_db.sqlalchemy.engines     result = self._query(query)
Jan 02 14:13:59 jfz1r03h11 devstack@placement-api.service[14363]: ERROR oslo_db.sqlalchemy.engines   File "/usr/local/lib/python2.7/dist-packages/pymysql/cursors.py", line 328, in _query
Jan 02 14:13:59 jfz1r03h11 devstack@placement-api.service[14363]: ERROR oslo_db.sqlalchemy.engines     conn.query(q)
Jan 02 14:13:59 jfz1r03h11 devstack@placement-api.service[14363]: ERROR oslo_db.sqlalchemy.engines   File "/usr/local/lib/python2.7/dist-packages/pymysql/connections.py", line 517, in query
Jan 02 14:13:59 jfz1r03h11 devstack@placement-api.service[14363]: ERROR oslo_db.sqlalchemy.engines     self._affected_rows = self._read_query_result(unbuffered=unbuffered)
Jan 02 14:13:59 jfz1r03h11 devstack@placement-api.service[14363]: ERROR oslo_db.sqlalchemy.engines   File "/usr/local/lib/python2.7/dist-packages/pymysql/connections.py", line 732, in _read_query_result
Jan 02 14:13:59 jfz1r03h11 devstack@placement-api.service[14363]: ERROR oslo_db.sqlalchemy.engines     result.read()
Jan 02 14:13:59 jfz1r03h11 devstack@placement-api.service[14363]: ERROR oslo_db.sqlalchemy.engines   File "/usr/local/lib/python2.7/dist-packages/pymysql/connections.py", line 1075, in read
Jan 02 14:13:59 jfz1r03h11 devstack@placement-api.service[14363]: ERROR oslo_db.sqlalchemy.engines     first_packet = self.connection._read_packet()
Jan 02 14:13:59 jfz1r03h11 devstack@placement-api.service[14363]: ERROR oslo_db.sqlalchemy.engines   File "/usr/local/lib/python2.7/dist-packages/pymysql/connections.py", line 657, in _read_packet
Jan 02 14:13:59 jfz1r03h11 devstack@placement-api.service[14363]: ERROR oslo_db.sqlalchemy.engines     packet_header = self._read_bytes(4)
Jan 02 14:13:59 jfz1r03h11 devstack@placement-api.service[14363]: ERROR oslo_db.sqlalchemy.engines   File "/usr/local/lib/python2.7/dist-packages/pymysql/connections.py", line 707, in _read_bytes
Jan 02 14:13:59 jfz1r03h11 devstack@placement-api.service[14363]: ERROR oslo_db.sqlalchemy.engines     CR.CR_SERVER_LOST, "Lost connection to MySQL server during query")
Jan 02 14:13:59 jfz1r03h11 devstack@placement-api.service[14363]: ERROR oslo_db.sqlalchemy.engines DBConnectionError: (pymysql.err.OperationalError) (2013, 'Lost connection to MySQL server during query') [SQL: u'SELECT 1'] (Background on this error at: http://sqlalche.me/e/e3q8)
Jan 02 14:13:59 jfz1r03h11 devstack@placement-api.service[14363]: ERROR oslo_db.sqlalchemy.engines 
Jan 02 14:13:59 jfz1r03h11 devstack@placement-api.service[14363]: INFO placement.requestlog [req-10ec9ad9-11dd-402d-bcf8-3c2e30df7026 req-7ebda97b-4cdb-40aa-a9fb-7a5f84e22799 service placement] 172.16.3.11 "GET /placement/resource_providers?in_tree=ec763e10-0c86-43eb-a2e0-25e429390a15" status: 200 len: 26 microversion: 1.14
Jan 02 14:13:59 jfz1r03h11 devstack@placement-api.service[14363]: [pid: 14367|app: 0|req: 30/530] 172.16.3.11 () {64 vars in 1451 bytes} [Wed Jan  2 14:13:59 2019] GET /placement/resource_providers?in_tree=ec763e10-0c86-43eb-a2e0-25e429390a15 => generated 26 bytes in 25 msecs (HTTP/1.1 200) 6 headers in 224 bytes (2 switches on core 0)
Jan 02 14:13:59 jfz1r03h11 devstack@placement-api.service[14363]: DEBUG placement.requestlog [req-10ec9ad9-11dd-402d-bcf8-3c2e30df7026 req-f8325a28-d673-41df-b643-4defb55fb332 service placement] Starting request: 172.16.3.11 "POST /placement/resource_providers" {{(pid=14370) __call__ /opt/stack/placement/placement/requestlog.py:38}}
Jan 02 14:13:59 jfz1r03h11 devstack@placement-api.service[14363]: ERROR oslo_db.sqlalchemy.engines [req-10ec9ad9-11dd-402d-bcf8-3c2e30df7026 req-f8325a28-d673-41df-b643-4defb55fb332 service placement] Database connection was found disconnected; reconnecting: DBConnectionError: (pymysql.err.OperationalError) (2013, 'Lost connection to MySQL server during query') [SQL: u'SELECT 1'] (Background on this error at: http://sqlalche.me/e/e3q8)
Jan 02 14:13:59 jfz1r03h11 devstack@placement-api.service[14363]: ERROR oslo_db.sqlalchemy.engines Traceback (most recent call last):
Jan 02 14:13:59 jfz1r03h11 devstack@placement-api.service[14363]: ERROR oslo_db.sqlalchemy.engines   File "/usr/local/lib/python2.7/dist-packages/oslo_db/sqlalchemy/engines.py", line 73, in _connect_ping_listener
Jan 02 14:13:59 jfz1r03h11 devstack@placement-api.service[14363]: ERROR oslo_db.sqlalchemy.engines     connection.scalar(select([1]))
Jan 02 14:13:59 jfz1r03h11 devstack@placement-api.service[14363]: ERROR oslo_db.sqlalchemy.engines   File "/usr/local/lib/python2.7/dist-packages/sqlalchemy/engine/base.py", line 880, in scalar
Jan 02 14:13:59 jfz1r03h11 devstack@placement-api.service[14363]: ERROR oslo_db.sqlalchemy.engines     return self.execute(object, *multiparams, **params).scalar()
Jan 02 14:13:59 jfz1r03h11 devstack@placement-api.service[14363]: ERROR oslo_db.sqlalchemy.engines   File "/usr/local/lib/python2.7/dist-packages/sqlalchemy/engine/base.py", line 948, in execute
Jan 02 14:13:59 jfz1r03h11 devstack@placement-api.service[14363]: ERROR oslo_db.sqlalchemy.engines     return meth(self, multiparams, params)
Jan 02 14:13:59 jfz1r03h11 devstack@placement-api.service[14363]: ERROR oslo_db.sqlalchemy.engines   File "/usr/local/lib/python2.7/dist-packages/sqlalchemy/sql/elements.py", line 269, in _execute_on_connection
Jan 02 14:13:59 jfz1r03h11 devstack@placement-api.service[14363]: ERROR oslo_db.sqlalchemy.engines     return connection._execute_clauseelement(self, multiparams, params)
Jan 02 14:13:59 jfz1r03h11 devstack@placement-api.service[14363]: ERROR oslo_db.sqlalchemy.engines   File "/usr/local/lib/python2.7/dist-packages/sqlalchemy/engine/base.py", line 1060, in _execute_clauseelement
Jan 02 14:13:59 jfz1r03h11 devstack@placement-api.service[14363]: ERROR oslo_db.sqlalchemy.engines     compiled_sql, distilled_params
Jan 02 14:13:59 jfz1r03h11 devstack@placement-api.service[14363]: ERROR oslo_db.sqlalchemy.engines   File "/usr/local/lib/python2.7/dist-packages/sqlalchemy/engine/base.py", line 1200, in _execute_context
Jan 02 14:13:59 jfz1r03h11 devstack@placement-api.service[14363]: ERROR oslo_db.sqlalchemy.engines     context)
Jan 02 14:13:59 jfz1r03h11 devstack@placement-api.service[14363]: ERROR oslo_db.sqlalchemy.engines   File "/usr/local/lib/python2.7/dist-packages/sqlalchemy/engine/base.py", line 1409, in _handle_dbapi_exception
Jan 02 14:13:59 jfz1r03h11 devstack@placement-api.service[14363]: ERROR oslo_db.sqlalchemy.engines     util.raise_from_cause(newraise, exc_info)
Jan 02 14:13:59 jfz1r03h11 devstack@placement-api.service[14363]: ERROR oslo_db.sqlalchemy.engines   File "/usr/local/lib/python2.7/dist-packages/sqlalchemy/util/compat.py", line 265, in raise_from_cause
Jan 02 14:13:59 jfz1r03h11 devstack@placement-api.service[14363]: ERROR oslo_db.sqlalchemy.engines     reraise(type(exception), exception, tb=exc_tb, cause=cause)
Jan 02 14:13:59 jfz1r03h11 devstack@placement-api.service[14363]: ERROR oslo_db.sqlalchemy.engines   File "/usr/local/lib/python2.7/dist-packages/sqlalchemy/engine/base.py", line 1193, in _execute_context
Jan 02 14:13:59 jfz1r03h11 devstack@placement-api.service[14363]: ERROR oslo_db.sqlalchemy.engines     context)
Jan 02 14:13:59 jfz1r03h11 devstack@placement-api.service[14363]: ERROR oslo_db.sqlalchemy.engines   File "/usr/local/lib/python2.7/dist-packages/sqlalchemy/engine/default.py", line 509, in do_execute
Jan 02 14:13:59 jfz1r03h11 devstack@placement-api.service[14363]: ERROR oslo_db.sqlalchemy.engines     cursor.execute(statement, parameters)
Jan 02 14:13:59 jfz1r03h11 devstack@placement-api.service[14363]: ERROR oslo_db.sqlalchemy.engines   File "/usr/local/lib/python2.7/dist-packages/pymysql/cursors.py", line 170, in execute
Jan 02 14:13:59 jfz1r03h11 devstack@placement-api.service[14363]: ERROR oslo_db.sqlalchemy.engines     result = self._query(query)
Jan 02 14:13:59 jfz1r03h11 devstack@placement-api.service[14363]: ERROR oslo_db.sqlalchemy.engines   File "/usr/local/lib/python2.7/dist-packages/pymysql/cursors.py", line 328, in _query
Jan 02 14:13:59 jfz1r03h11 devstack@placement-api.service[14363]: ERROR oslo_db.sqlalchemy.engines     conn.query(q)
Jan 02 14:13:59 jfz1r03h11 devstack@placement-api.service[14363]: ERROR oslo_db.sqlalchemy.engines   File "/usr/local/lib/python2.7/dist-packages/pymysql/connections.py", line 517, in query
Jan 02 14:13:59 jfz1r03h11 devstack@placement-api.service[14363]: ERROR oslo_db.sqlalchemy.engines     self._affected_rows = self._read_query_result(unbuffered=unbuffered)
Jan 02 14:13:59 jfz1r03h11 devstack@placement-api.service[14363]: ERROR oslo_db.sqlalchemy.engines   File "/usr/local/lib/python2.7/dist-packages/pymysql/connections.py", line 732, in _read_query_result
Jan 02 14:13:59 jfz1r03h11 devstack@placement-api.service[14363]: ERROR oslo_db.sqlalchemy.engines     result.read()
Jan 02 14:13:59 jfz1r03h11 devstack@placement-api.service[14363]: ERROR oslo_db.sqlalchemy.engines   File "/usr/local/lib/python2.7/dist-packages/pymysql/connections.py", line 1075, in read
Jan 02 14:13:59 jfz1r03h11 devstack@placement-api.service[14363]: ERROR oslo_db.sqlalchemy.engines     first_packet = self.connection._read_packet()
Jan 02 14:13:59 jfz1r03h11 devstack@placement-api.service[14363]: ERROR oslo_db.sqlalchemy.engines   File "/usr/local/lib/python2.7/dist-packages/pymysql/connections.py", line 657, in _read_packet
Jan 02 14:13:59 jfz1r03h11 devstack@placement-api.service[14363]: ERROR oslo_db.sqlalchemy.engines     packet_header = self._read_bytes(4)
Jan 02 14:13:59 jfz1r03h11 devstack@placement-api.service[14363]: ERROR oslo_db.sqlalchemy.engines   File "/usr/local/lib/python2.7/dist-packages/pymysql/connections.py", line 707, in _read_bytes
Jan 02 14:13:59 jfz1r03h11 devstack@placement-api.service[14363]: ERROR oslo_db.sqlalchemy.engines     CR.CR_SERVER_LOST, "Lost connection to MySQL server during query")
Jan 02 14:13:59 jfz1r03h11 devstack@placement-api.service[14363]: ERROR oslo_db.sqlalchemy.engines DBConnectionError: (pymysql.err.OperationalError) (2013, 'Lost connection to MySQL server during query') [SQL: u'SELECT 1'] (Background on this error at: http://sqlalche.me/e/e3q8)
Jan 02 14:13:59 jfz1r03h11 devstack@placement-api.service[14363]: ERROR oslo_db.sqlalchemy.engines 
Jan 02 14:13:59 jfz1r03h11 devstack@placement-api.service[14363]: DEBUG placement.wsgi_wrapper [req-10ec9ad9-11dd-402d-bcf8-3c2e30df7026 req-f8325a28-d673-41df-b643-4defb55fb332 service placement] Placement API returning an error response: Conflicting resource provider name: jfz1r03h11 already exists. {{(pid=14370) call_func /opt/stack/placement/placement/wsgi_wrapper.py:31}}
Jan 02 14:13:59 jfz1r03h11 devstack@placement-api.service[14363]: INFO placement.requestlog [req-10ec9ad9-11dd-402d-bcf8-3c2e30df7026 req-f8325a28-d673-41df-b643-4defb55fb332 service placement] 172.16.3.11 "POST /placement/resource_providers" status: 409 len: 249 microversion: 1.20
Jan 02 14:13:59 jfz1r03h11 devstack@placement-api.service[14363]: [pid: 14370|app: 0|req: 30/531] 172.16.3.11 () {68 vars in 1415 bytes} [Wed Jan  2 14:13:59 2019] POST /placement/resource_providers => generated 249 bytes in 22 msecs (HTTP/1.1 409) 6 headers in 231 bytes (1 switches on core 0)
Jan 02 14:15:01 jfz1r03h11 devstack@placement-api.service[14363]: WARNING keystonemiddleware.auth_token [req-ff0a3fc7-899e-40be-8584-76605f5c19b7 req-ac24ac10-6656-4294-a194-3a7420fe5c9a service placement] Identity response: {"error":{"code":401,"message":"The request you have made requires authentication.","title":"Unauthorized"}}
Jan 02 14:15:01 jfz1r03h11 devstack@placement-api.service[14363]: : Unauthorized: The request you have made requires authentication. (HTTP 401) (Request-ID: req-36c02a93-abfc-4661-9ed5-e525abcc0323)
Jan 02 14:15:01 jfz1r03h11 devstack@placement-api.service[14363]: WARNING keystonemiddleware.auth_token [req-ff0a3fc7-899e-40be-8584-76605f5c19b7 req-ac24ac10-6656-4294-a194-3a7420fe5c9a service placement] Identity response: {"error":{"code":401,"message":"The request you have made requires authentication.","title":"Unauthorized"}}
Jan 02 14:15:01 jfz1r03h11 devstack@placement-api.service[14363]: : Unauthorized: The request you have made requires authentication. (HTTP 401) (Request-ID: req-e9d7caef-bbff-46e3-8a07-046172f50d43)
Jan 02 14:15:01 jfz1r03h11 devstack@placement-api.service[14363]: CRITICAL keystonemiddleware.auth_token [req-ff0a3fc7-899e-40be-8584-76605f5c19b7 req-ac24ac10-6656-4294-a194-3a7420fe5c9a service placement] Unable to validate token: Identity server rejected authorization necessary to fetch token data: ServiceError: Identity server rejected authorization necessary to fetch token data
Jan 02 14:15:01 jfz1r03h11 devstack@placement-api.service[14363]: [pid: 14379|app: 0|req: 30/532] 172.16.3.11 () {62 vars in 1465 bytes} [Wed Jan  2 14:15:01 2019] GET /placement/resource_providers/ec763e10-0c86-43eb-a2e0-25e429390a15/allocations => generated 218 bytes in 110 msecs (HTTP/1.1 503) 4 headers in 174 bytes (2 switches on core 0)
Jan 02 14:15:01 jfz1r03h11 devstack@placement-api.service[14363]: WARNING keystonemiddleware.auth_token [req-ff0a3fc7-899e-40be-8584-76605f5c19b7 req-d1ba82e5-8919-4a75-914c-223e361173ba service placement] Identity response: {"error":{"code":401,"message":"The request you have made requires authentication.","title":"Unauthorized"}}
Jan 02 14:15:01 jfz1r03h11 devstack@placement-api.service[14363]: : Unauthorized: The request you have made requires authentication. (HTTP 401) (Request-ID: req-84b330af-3d93-490a-a2ff-eb8879daff8b)
Jan 02 14:15:01 jfz1r03h11 devstack@placement-api.service[14363]: WARNING keystonemiddleware.auth_token [req-ff0a3fc7-899e-40be-8584-76605f5c19b7 req-d1ba82e5-8919-4a75-914c-223e361173ba service placement] Identity response: {"error":{"code":401,"message":"The request you have made requires authentication.","title":"Unauthorized"}}
Jan 02 14:15:01 jfz1r03h11 devstack@placement-api.service[14363]: : Unauthorized: The request you have made requires authentication. (HTTP 401) (Request-ID: req-4e7203ed-e820-4c7e-bee5-73134de8173e)
Jan 02 14:15:01 jfz1r03h11 devstack@placement-api.service[14363]: CRITICAL keystonemiddleware.auth_token [req-ff0a3fc7-899e-40be-8584-76605f5c19b7 req-d1ba82e5-8919-4a75-914c-223e361173ba service placement] Unable to validate token: Identity server rejected authorization necessary to fetch token data: ServiceError: Identity server rejected authorization necessary to fetch token data
Jan 02 14:15:01 jfz1r03h11 devstack@placement-api.service[14363]: [pid: 14373|app: 0|req: 30/533] 172.16.3.11 () {64 vars in 1451 bytes} [Wed Jan  2 14:15:01 2019] GET /placement/resource_providers?in_tree=ec763e10-0c86-43eb-a2e0-25e429390a15 => generated 218 bytes in 71 msecs (HTTP/1.1 503) 4 headers in 174 bytes (2 switches on core 0)
Jan 02 14:16:03 jfz1r03h11 devstack@placement-api.service[14363]: WARNING keystonemiddleware.auth_token [req-ff0a3fc7-899e-40be-8584-76605f5c19b7 req-a1460498-7643-4c9a-b5d3-89e790643b96 service placement] Identity response: {"error":{"code":401,"message":"The request you have made requires authentication.","title":"Unauthorized"}}
Jan 02 14:16:03 jfz1r03h11 devstack@placement-api.service[14363]: : Unauthorized: The request you have made requires authentication. (HTTP 401) (Request-ID: req-0a321ab5-6ae2-4b3d-97c8-66f0fb6f4247)
Jan 02 14:16:03 jfz1r03h11 devstack@placement-api.service[14363]: WARNING keystonemiddleware.auth_token [req-ff0a3fc7-899e-40be-8584-76605f5c19b7 req-a1460498-7643-4c9a-b5d3-89e790643b96 service placement] Identity response: {"error":{"code":401,"message":"The request you have made requires authentication.","title":"Unauthorized"}}
Jan 02 14:16:03 jfz1r03h11 devstack@placement-api.service[14363]: : Unauthorized: The request you have made requires authentication. (HTTP 401) (Request-ID: req-aed2947a-dd86-4418-99b3-e68ea02b5f51)
Jan 02 14:16:03 jfz1r03h11 devstack@placement-api.service[14363]: CRITICAL keystonemiddleware.auth_token [req-ff0a3fc7-899e-40be-8584-76605f5c19b7 req-a1460498-7643-4c9a-b5d3-89e790643b96 service placement] Unable to validate token: Identity server rejected authorization necessary to fetch token data: ServiceError: Identity server rejected authorization necessary to fetch token data
Jan 02 14:16:03 jfz1r03h11 devstack@placement-api.service[14363]: [pid: 14377|app: 0|req: 30/534] 172.16.3.11 () {62 vars in 1465 bytes} [Wed Jan  2 14:16:03 2019] GET /placement/resource_providers/ec763e10-0c86-43eb-a2e0-25e429390a15/allocations => generated 218 bytes in 67 msecs (HTTP/1.1 503) 4 headers in 174 bytes (1 switches on core 0)
Jan 02 14:16:03 jfz1r03h11 devstack@placement-api.service[14363]: WARNING keystonemiddleware.auth_token [req-773bdffe-c075-451d-9b71-40038ab9160f req-aa2c6f36-96c0-4789-b3c3-e46e78e36fc4 service placement] Identity response: {"error":{"code":401,"message":"The request you have made requires authentication.","title":"Unauthorized"}}
Jan 02 14:16:03 jfz1r03h11 devstack@placement-api.service[14363]: : Unauthorized: The request you have made requires authentication. (HTTP 401) (Request-ID: req-9bc9cdf3-da22-4d5f-8f63-4b107c5d599c)
Jan 02 14:16:03 jfz1r03h11 devstack@placement-api.service[14363]: WARNING keystonemiddleware.auth_token [req-773bdffe-c075-451d-9b71-40038ab9160f req-aa2c6f36-96c0-4789-b3c3-e46e78e36fc4 service placement] Identity response: {"error":{"code":401,"message":"The request you have made requires authentication.","title":"Unauthorized"}}
Jan 02 14:16:03 jfz1r03h11 devstack@placement-api.service[14363]: : Unauthorized: The request you have made requires authentication. (HTTP 401) (Request-ID: req-811713fa-bcae-429d-91ff-8791d2ed964e)
Jan 02 14:16:03 jfz1r03h11 devstack@placement-api.service[14363]: CRITICAL keystonemiddleware.auth_token [req-773bdffe-c075-451d-9b71-40038ab9160f req-aa2c6f36-96c0-4789-b3c3-e46e78e36fc4 service placement] Unable to validate token: Identity server rejected authorization necessary to fetch token data: ServiceError: Identity server rejected authorization necessary to fetch token data
Jan 02 14:16:03 jfz1r03h11 devstack@placement-api.service[14363]: [pid: 14383|app: 0|req: 30/535] 172.16.3.11 () {64 vars in 1451 bytes} [Wed Jan  2 14:16:03 2019] GET /placement/resource_providers?in_tree=ec763e10-0c86-43eb-a2e0-25e429390a15 => generated 218 bytes in 93 msecs (HTTP/1.1 503) 4 headers in 174 bytes (1 switches on core 0)
Jan 02 14:17:05 jfz1r03h11 devstack@placement-api.service[14363]: WARNING keystonemiddleware.auth_token [req-773bdffe-c075-451d-9b71-40038ab9160f req-a4812707-9c28-46ea-bbdd-718d19b1febc service placement] Identity response: {"error":{"code":401,"message":"The request you have made requires authentication.","title":"Unauthorized"}}
Jan 02 14:17:05 jfz1r03h11 devstack@placement-api.service[14363]: : Unauthorized: The request you have made requires authentication. (HTTP 401) (Request-ID: req-457fe9d6-4d12-43dc-ad50-1a3853e5d287)
Jan 02 14:17:05 jfz1r03h11 devstack@placement-api.service[14363]: WARNING keystonemiddleware.auth_token [req-773bdffe-c075-451d-9b71-40038ab9160f req-a4812707-9c28-46ea-bbdd-718d19b1febc service placement] Identity response: {"error":{"code":401,"message":"The request you have made requires authentication.","title":"Unauthorized"}}
Jan 02 14:17:05 jfz1r03h11 devstack@placement-api.service[14363]: : Unauthorized: The request you have made requires authentication. (HTTP 401) (Request-ID: req-0d830c6b-beb4-4389-b55d-a608f68c4ba8)
Jan 02 14:17:05 jfz1r03h11 devstack@placement-api.service[14363]: CRITICAL keystonemiddleware.auth_token [req-773bdffe-c075-451d-9b71-40038ab9160f req-a4812707-9c28-46ea-bbdd-718d19b1febc service placement] Unable to validate token: Identity server rejected authorization necessary to fetch token data: ServiceError: Identity server rejected authorization necessary to fetch token data
Jan 02 14:17:05 jfz1r03h11 devstack@placement-api.service[14363]: [pid: 14368|app: 0|req: 30/536] 172.16.3.11 () {62 vars in 1465 bytes} [Wed Jan  2 14:17:05 2019] GET /placement/resource_providers/ec763e10-0c86-43eb-a2e0-25e429390a15/allocations => generated 218 bytes in 83 msecs (HTTP/1.1 503) 4 headers in 174 bytes (1 switches on core 0)
Jan 02 14:17:05 jfz1r03h11 devstack@placement-api.service[14363]: WARNING keystonemiddleware.auth_token [req-773bdffe-c075-451d-9b71-40038ab9160f req-df30dae9-ef53-4e8e-9e35-8d4b67074557 service placement] Identity response: {"error":{"code":401,"message":"The request you have made requires authentication.","title":"Unauthorized"}}
Jan 02 14:17:05 jfz1r03h11 devstack@placement-api.service[14363]: : Unauthorized: The request you have made requires authentication. (HTTP 401) (Request-ID: req-09ed7c19-6836-4bb8-ab34-d2238ea4b43a)
Jan 02 14:17:05 jfz1r03h11 devstack@placement-api.service[14363]: WARNING keystonemiddleware.auth_token [req-773bdffe-c075-451d-9b71-40038ab9160f req-df30dae9-ef53-4e8e-9e35-8d4b67074557 service placement] Identity response: {"error":{"code":401,"message":"The request you have made requires authentication.","title":"Unauthorized"}}
Jan 02 14:17:05 jfz1r03h11 devstack@placement-api.service[14363]: : Unauthorized: The request you have made requires authentication. (HTTP 401) (Request-ID: req-d34f6770-3eb8-4030-b86a-61844897833c)
Jan 02 14:17:05 jfz1r03h11 devstack@placement-api.service[14363]: CRITICAL keystonemiddleware.auth_token [req-773bdffe-c075-451d-9b71-40038ab9160f req-df30dae9-ef53-4e8e-9e35-8d4b67074557 service placement] Unable to validate token: Identity server rejected authorization necessary to fetch token data: ServiceError: Identity server rejected authorization necessary to fetch token data
Jan 02 14:17:05 jfz1r03h11 devstack@placement-api.service[14363]: [pid: 14382|app: 0|req: 30/537] 172.16.3.11 () {64 vars in 1451 bytes} [Wed Jan  2 14:17:05 2019] GET /placement/resource_providers?in_tree=ec763e10-0c86-43eb-a2e0-25e429390a15 => generated 218 bytes in 80 msecs (HTTP/1.1 503) 4 headers in 174 bytes (2 switches on core 0)
Jan 02 14:18:05 jfz1r03h11 devstack@placement-api.service[14363]: WARNING keystonemiddleware.auth_token [req-d69c07ae-5862-4596-ab2f-4946d6999593 req-490241b7-2fa0-4526-96c6-5862b7a0fa92 service placement] Identity response: {"error":{"code":401,"message":"The request you have made requires authentication.","title":"Unauthorized"}}
Jan 02 14:18:05 jfz1r03h11 devstack@placement-api.service[14363]: : Unauthorized: The request you have made requires authentication. (HTTP 401) (Request-ID: req-8889189d-5be8-4db5-8fc2-7dcb4bc701bb)
Jan 02 14:18:05 jfz1r03h11 devstack@placement-api.service[14363]: WARNING keystonemiddleware.auth_token [req-d69c07ae-5862-4596-ab2f-4946d6999593 req-490241b7-2fa0-4526-96c6-5862b7a0fa92 service placement] Identity response: {"error":{"code":401,"message":"The request you have made requires authentication.","title":"Unauthorized"}}
Jan 02 14:18:05 jfz1r03h11 devstack@placement-api.service[14363]: : Unauthorized: The request you have made requires authentication. (HTTP 401) (Request-ID: req-8f430bdf-105c-4327-ac43-ea93f77aed52)
Jan 02 14:18:05 jfz1r03h11 devstack@placement-api.service[14363]: CRITICAL keystonemiddleware.auth_token [req-d69c07ae-5862-4596-ab2f-4946d6999593 req-490241b7-2fa0-4526-96c6-5862b7a0fa92 service placement] Unable to validate token: Identity server rejected authorization necessary to fetch token data: ServiceError: Identity server rejected authorization necessary to fetch token data
Jan 02 14:18:05 jfz1r03h11 devstack@placement-api.service[14363]: [pid: 14384|app: 0|req: 30/538] 172.16.3.11 () {62 vars in 1465 bytes} [Wed Jan  2 14:18:05 2019] GET /placement/resource_providers/ec763e10-0c86-43eb-a2e0-25e429390a15/allocations => generated 218 bytes in 96 msecs (HTTP/1.1 503) 4 headers in 174 bytes (1 switches on core 0)
Jan 02 14:18:05 jfz1r03h11 devstack@placement-api.service[14363]: WARNING keystonemiddleware.auth_token [req-d69c07ae-5862-4596-ab2f-4946d6999593 req-e5383d0c-fc4a-4f08-af10-f16f48faa692 service placement] Identity response: {"error":{"code":401,"message":"The request you have made requires authentication.","title":"Unauthorized"}}
Jan 02 14:18:05 jfz1r03h11 devstack@placement-api.service[14363]: : Unauthorized: The request you have made requires authentication. (HTTP 401) (Request-ID: req-81bb55cf-290d-46b1-98d7-83eac23773a4)
Jan 02 14:18:05 jfz1r03h11 devstack@placement-api.service[14363]: WARNING keystonemiddleware.auth_token [req-d69c07ae-5862-4596-ab2f-4946d6999593 req-e5383d0c-fc4a-4f08-af10-f16f48faa692 service placement] Identity response: {"error":{"code":401,"message":"The request you have made requires authentication.","title":"Unauthorized"}}
Jan 02 14:18:05 jfz1r03h11 devstack@placement-api.service[14363]: : Unauthorized: The request you have made requires authentication. (HTTP 401) (Request-ID: req-b5e069bd-3050-4d56-b498-6a570dc59b4b)
Jan 02 14:18:05 jfz1r03h11 devstack@placement-api.service[14363]: CRITICAL keystonemiddleware.auth_token [req-d69c07ae-5862-4596-ab2f-4946d6999593 req-e5383d0c-fc4a-4f08-af10-f16f48faa692 service placement] Unable to validate token: Identity server rejected authorization necessary to fetch token data: ServiceError: Identity server rejected authorization necessary to fetch token data
Jan 02 14:18:05 jfz1r03h11 devstack@placement-api.service[14363]: [pid: 14378|app: 0|req: 30/539] 172.16.3.11 () {64 vars in 1451 bytes} [Wed Jan  2 14:18:05 2019] GET /placement/resource_providers?in_tree=ec763e10-0c86-43eb-a2e0-25e429390a15 => generated 218 bytes in 74 msecs (HTTP/1.1 503) 4 headers in 174 bytes (1 switches on core 0)
Jan 02 14:19:05 jfz1r03h11 devstack@placement-api.service[14363]: WARNING keystonemiddleware.auth_token [req-d69c07ae-5862-4596-ab2f-4946d6999593 req-3c06ab99-ceda-489c-9863-93636415bda8 service placement] Authorization failed for token: InvalidToken: Token authorization failed
Jan 02 14:19:05 jfz1r03h11 devstack@placement-api.service[14363]: [pid: 14371|app: 0|req: 30/540] 172.16.3.11 () {62 vars in 1465 bytes} [Wed Jan  2 14:19:05 2019] GET /placement/resource_providers/ec763e10-0c86-43eb-a2e0-25e429390a15/allocations => generated 114 bytes in 229 msecs (HTTP/1.1 401) 5 headers in 229 bytes (2 switches on core 0)
Jan 02 14:19:05 jfz1r03h11 devstack@placement-api.service[14363]: DEBUG placement.requestlog [req-cbe2fff6-f0a3-454e-8368-9556cc3f3690 req-f481cd63-770f-458f-b6e0-1d3b15dadfae service placement] Starting request: 172.16.3.11 "GET /placement/resource_providers/ec763e10-0c86-43eb-a2e0-25e429390a15/allocations" {{(pid=14375) __call__ /opt/stack/placement/placement/requestlog.py:38}}
Jan 02 14:19:05 jfz1r03h11 devstack@placement-api.service[14363]: ERROR oslo_db.sqlalchemy.engines [req-cbe2fff6-f0a3-454e-8368-9556cc3f3690 req-f481cd63-770f-458f-b6e0-1d3b15dadfae service placement] Database connection was found disconnected; reconnecting: DBConnectionError: (pymysql.err.OperationalError) (2013, 'Lost connection to MySQL server during query') [SQL: u'SELECT 1'] (Background on this error at: http://sqlalche.me/e/e3q8)
Jan 02 14:19:05 jfz1r03h11 devstack@placement-api.service[14363]: ERROR oslo_db.sqlalchemy.engines Traceback (most recent call last):
Jan 02 14:19:05 jfz1r03h11 devstack@placement-api.service[14363]: ERROR oslo_db.sqlalchemy.engines   File "/usr/local/lib/python2.7/dist-packages/oslo_db/sqlalchemy/engines.py", line 73, in _connect_ping_listener
Jan 02 14:19:05 jfz1r03h11 devstack@placement-api.service[14363]: ERROR oslo_db.sqlalchemy.engines     connection.scalar(select([1]))
Jan 02 14:19:05 jfz1r03h11 devstack@placement-api.service[14363]: ERROR oslo_db.sqlalchemy.engines   File "/usr/local/lib/python2.7/dist-packages/sqlalchemy/engine/base.py", line 880, in scalar
Jan 02 14:19:05 jfz1r03h11 devstack@placement-api.service[14363]: ERROR oslo_db.sqlalchemy.engines     return self.execute(object, *multiparams, **params).scalar()
Jan 02 14:19:05 jfz1r03h11 devstack@placement-api.service[14363]: ERROR oslo_db.sqlalchemy.engines   File "/usr/local/lib/python2.7/dist-packages/sqlalchemy/engine/base.py", line 948, in execute
Jan 02 14:19:05 jfz1r03h11 devstack@placement-api.service[14363]: ERROR oslo_db.sqlalchemy.engines     return meth(self, multiparams, params)
Jan 02 14:19:05 jfz1r03h11 devstack@placement-api.service[14363]: ERROR oslo_db.sqlalchemy.engines   File "/usr/local/lib/python2.7/dist-packages/sqlalchemy/sql/elements.py", line 269, in _execute_on_connection
Jan 02 14:19:05 jfz1r03h11 devstack@placement-api.service[14363]: ERROR oslo_db.sqlalchemy.engines     return connection._execute_clauseelement(self, multiparams, params)
Jan 02 14:19:05 jfz1r03h11 devstack@placement-api.service[14363]: ERROR oslo_db.sqlalchemy.engines   File "/usr/local/lib/python2.7/dist-packages/sqlalchemy/engine/base.py", line 1060, in _execute_clauseelement
Jan 02 14:19:05 jfz1r03h11 devstack@placement-api.service[14363]: ERROR oslo_db.sqlalchemy.engines     compiled_sql, distilled_params
Jan 02 14:19:05 jfz1r03h11 devstack@placement-api.service[14363]: ERROR oslo_db.sqlalchemy.engines   File "/usr/local/lib/python2.7/dist-packages/sqlalchemy/engine/base.py", line 1200, in _execute_context
Jan 02 14:19:05 jfz1r03h11 devstack@placement-api.service[14363]: ERROR oslo_db.sqlalchemy.engines     context)
Jan 02 14:19:05 jfz1r03h11 devstack@placement-api.service[14363]: ERROR oslo_db.sqlalchemy.engines   File "/usr/local/lib/python2.7/dist-packages/sqlalchemy/engine/base.py", line 1409, in _handle_dbapi_exception
Jan 02 14:19:05 jfz1r03h11 devstack@placement-api.service[14363]: ERROR oslo_db.sqlalchemy.engines     util.raise_from_cause(newraise, exc_info)
Jan 02 14:19:05 jfz1r03h11 devstack@placement-api.service[14363]: ERROR oslo_db.sqlalchemy.engines   File "/usr/local/lib/python2.7/dist-packages/sqlalchemy/util/compat.py", line 265, in raise_from_cause
Jan 02 14:19:05 jfz1r03h11 devstack@placement-api.service[14363]: ERROR oslo_db.sqlalchemy.engines     reraise(type(exception), exception, tb=exc_tb, cause=cause)
Jan 02 14:19:05 jfz1r03h11 devstack@placement-api.service[14363]: ERROR oslo_db.sqlalchemy.engines   File "/usr/local/lib/python2.7/dist-packages/sqlalchemy/engine/base.py", line 1193, in _execute_context
Jan 02 14:19:05 jfz1r03h11 devstack@placement-api.service[14363]: ERROR oslo_db.sqlalchemy.engines     context)
Jan 02 14:19:05 jfz1r03h11 devstack@placement-api.service[14363]: ERROR oslo_db.sqlalchemy.engines   File "/usr/local/lib/python2.7/dist-packages/sqlalchemy/engine/default.py", line 509, in do_execute
Jan 02 14:19:05 jfz1r03h11 devstack@placement-api.service[14363]: ERROR oslo_db.sqlalchemy.engines     cursor.execute(statement, parameters)
Jan 02 14:19:05 jfz1r03h11 devstack@placement-api.service[14363]: ERROR oslo_db.sqlalchemy.engines   File "/usr/local/lib/python2.7/dist-packages/pymysql/cursors.py", line 170, in execute
Jan 02 14:19:05 jfz1r03h11 devstack@placement-api.service[14363]: ERROR oslo_db.sqlalchemy.engines     result = self._query(query)
Jan 02 14:19:05 jfz1r03h11 devstack@placement-api.service[14363]: ERROR oslo_db.sqlalchemy.engines   File "/usr/local/lib/python2.7/dist-packages/pymysql/cursors.py", line 328, in _query
Jan 02 14:19:05 jfz1r03h11 devstack@placement-api.service[14363]: ERROR oslo_db.sqlalchemy.engines     conn.query(q)
Jan 02 14:19:05 jfz1r03h11 devstack@placement-api.service[14363]: ERROR oslo_db.sqlalchemy.engines   File "/usr/local/lib/python2.7/dist-packages/pymysql/connections.py", line 517, in query
Jan 02 14:19:05 jfz1r03h11 devstack@placement-api.service[14363]: ERROR oslo_db.sqlalchemy.engines     self._affected_rows = self._read_query_result(unbuffered=unbuffered)
Jan 02 14:19:05 jfz1r03h11 devstack@placement-api.service[14363]: ERROR oslo_db.sqlalchemy.engines   File "/usr/local/lib/python2.7/dist-packages/pymysql/connections.py", line 732, in _read_query_result
Jan 02 14:19:05 jfz1r03h11 devstack@placement-api.service[14363]: ERROR oslo_db.sqlalchemy.engines     result.read()
Jan 02 14:19:05 jfz1r03h11 devstack@placement-api.service[14363]: ERROR oslo_db.sqlalchemy.engines   File "/usr/local/lib/python2.7/dist-packages/pymysql/connections.py", line 1075, in read
Jan 02 14:19:05 jfz1r03h11 devstack@placement-api.service[14363]: ERROR oslo_db.sqlalchemy.engines     first_packet = self.connection._read_packet()
Jan 02 14:19:05 jfz1r03h11 devstack@placement-api.service[14363]: ERROR oslo_db.sqlalchemy.engines   File "/usr/local/lib/python2.7/dist-packages/pymysql/connections.py", line 657, in _read_packet
Jan 02 14:19:05 jfz1r03h11 devstack@placement-api.service[14363]: ERROR oslo_db.sqlalchemy.engines     packet_header = self._read_bytes(4)
Jan 02 14:19:05 jfz1r03h11 devstack@placement-api.service[14363]: ERROR oslo_db.sqlalchemy.engines   File "/usr/local/lib/python2.7/dist-packages/pymysql/connections.py", line 707, in _read_bytes
Jan 02 14:19:05 jfz1r03h11 devstack@placement-api.service[14363]: ERROR oslo_db.sqlalchemy.engines     CR.CR_SERVER_LOST, "Lost connection to MySQL server during query")
Jan 02 14:19:05 jfz1r03h11 devstack@placement-api.service[14363]: ERROR oslo_db.sqlalchemy.engines DBConnectionError: (pymysql.err.OperationalError) (2013, 'Lost connection to MySQL server during query') [SQL: u'SELECT 1'] (Background on this error at: http://sqlalche.me/e/e3q8)
Jan 02 14:19:05 jfz1r03h11 devstack@placement-api.service[14363]: ERROR oslo_db.sqlalchemy.engines 
Jan 02 14:19:05 jfz1r03h11 devstack@placement-api.service[14363]: DEBUG placement.wsgi_wrapper [req-cbe2fff6-f0a3-454e-8368-9556cc3f3690 req-f481cd63-770f-458f-b6e0-1d3b15dadfae service placement] Placement API returning an error response: Resource provider 'ec763e10-0c86-43eb-a2e0-25e429390a15' not found: No resource provider with uuid ec763e10-0c86-43eb-a2e0-25e429390a15 found {{(pid=14375) call_func /opt/stack/placement/placement/wsgi_wrapper.py:31}}
Jan 02 14:19:05 jfz1r03h11 devstack@placement-api.service[14363]: INFO placement.requestlog [req-cbe2fff6-f0a3-454e-8368-9556cc3f3690 req-f481cd63-770f-458f-b6e0-1d3b15dadfae service placement] 172.16.3.11 "GET /placement/resource_providers/ec763e10-0c86-43eb-a2e0-25e429390a15/allocations" status: 404 len: 303 microversion: 1.0
Jan 02 14:19:05 jfz1r03h11 devstack@placement-api.service[14363]: [pid: 14375|app: 0|req: 30/541] 172.16.3.11 () {62 vars in 1465 bytes} [Wed Jan  2 14:19:05 2019] GET /placement/resource_providers/ec763e10-0c86-43eb-a2e0-25e429390a15/allocations => generated 303 bytes in 214 msecs (HTTP/1.1 404) 6 headers in 231 bytes (1 switches on core 0)
Jan 02 14:20:07 jfz1r03h11 devstack@placement-api.service[14363]: DEBUG placement.requestlog [req-6ba7aad8-997a-4851-ae1a-6f60f088f466 req-21e651e2-efce-41d9-939d-94efc219836e service placement] Starting request: 172.16.3.11 "GET /placement/resource_providers?in_tree=39144ddc-c0a4-4deb-9436-7903c9f298ca" {{(pid=14374) __call__ /opt/stack/placement/placement/requestlog.py:38}}
Jan 02 14:20:07 jfz1r03h11 devstack@placement-api.service[14363]: ERROR oslo_db.sqlalchemy.engines [req-6ba7aad8-997a-4851-ae1a-6f60f088f466 req-21e651e2-efce-41d9-939d-94efc219836e service placement] Database connection was found disconnected; reconnecting: DBConnectionError: (pymysql.err.OperationalError) (2013, 'Lost connection to MySQL server during query') [SQL: u'SELECT 1'] (Background on this error at: http://sqlalche.me/e/e3q8)
Jan 02 14:20:07 jfz1r03h11 devstack@placement-api.service[14363]: ERROR oslo_db.sqlalchemy.engines Traceback (most recent call last):
Jan 02 14:20:07 jfz1r03h11 devstack@placement-api.service[14363]: ERROR oslo_db.sqlalchemy.engines   File "/usr/local/lib/python2.7/dist-packages/oslo_db/sqlalchemy/engines.py", line 73, in _connect_ping_listener
Jan 02 14:20:07 jfz1r03h11 devstack@placement-api.service[14363]: ERROR oslo_db.sqlalchemy.engines     connection.scalar(select([1]))
Jan 02 14:20:07 jfz1r03h11 devstack@placement-api.service[14363]: ERROR oslo_db.sqlalchemy.engines   File "/usr/local/lib/python2.7/dist-packages/sqlalchemy/engine/base.py", line 880, in scalar
Jan 02 14:20:07 jfz1r03h11 devstack@placement-api.service[14363]: ERROR oslo_db.sqlalchemy.engines     return self.execute(object, *multiparams, **params).scalar()
Jan 02 14:20:07 jfz1r03h11 devstack@placement-api.service[14363]: ERROR oslo_db.sqlalchemy.engines   File "/usr/local/lib/python2.7/dist-packages/sqlalchemy/engine/base.py", line 948, in execute
Jan 02 14:20:07 jfz1r03h11 devstack@placement-api.service[14363]: ERROR oslo_db.sqlalchemy.engines     return meth(self, multiparams, params)
Jan 02 14:20:07 jfz1r03h11 devstack@placement-api.service[14363]: ERROR oslo_db.sqlalchemy.engines   File "/usr/local/lib/python2.7/dist-packages/sqlalchemy/sql/elements.py", line 269, in _execute_on_connection
Jan 02 14:20:07 jfz1r03h11 devstack@placement-api.service[14363]: ERROR oslo_db.sqlalchemy.engines     return connection._execute_clauseelement(self, multiparams, params)
Jan 02 14:20:07 jfz1r03h11 devstack@placement-api.service[14363]: ERROR oslo_db.sqlalchemy.engines   File "/usr/local/lib/python2.7/dist-packages/sqlalchemy/engine/base.py", line 1060, in _execute_clauseelement
Jan 02 14:20:07 jfz1r03h11 devstack@placement-api.service[14363]: ERROR oslo_db.sqlalchemy.engines     compiled_sql, distilled_params
Jan 02 14:20:07 jfz1r03h11 devstack@placement-api.service[14363]: ERROR oslo_db.sqlalchemy.engines   File "/usr/local/lib/python2.7/dist-packages/sqlalchemy/engine/base.py", line 1200, in _execute_context
Jan 02 14:20:07 jfz1r03h11 devstack@placement-api.service[14363]: ERROR oslo_db.sqlalchemy.engines     context)
Jan 02 14:20:07 jfz1r03h11 devstack@placement-api.service[14363]: ERROR oslo_db.sqlalchemy.engines   File "/usr/local/lib/python2.7/dist-packages/sqlalchemy/engine/base.py", line 1409, in _handle_dbapi_exception
Jan 02 14:20:07 jfz1r03h11 devstack@placement-api.service[14363]: ERROR oslo_db.sqlalchemy.engines     util.raise_from_cause(newraise, exc_info)
Jan 02 14:20:07 jfz1r03h11 devstack@placement-api.service[14363]: ERROR oslo_db.sqlalchemy.engines   File "/usr/local/lib/python2.7/dist-packages/sqlalchemy/util/compat.py", line 265, in raise_from_cause
Jan 02 14:20:07 jfz1r03h11 devstack@placement-api.service[14363]: ERROR oslo_db.sqlalchemy.engines     reraise(type(exception), exception, tb=exc_tb, cause=cause)
Jan 02 14:20:07 jfz1r03h11 devstack@placement-api.service[14363]: ERROR oslo_db.sqlalchemy.engines   File "/usr/local/lib/python2.7/dist-packages/sqlalchemy/engine/base.py", line 1193, in _execute_context
Jan 02 14:20:07 jfz1r03h11 devstack@placement-api.service[14363]: ERROR oslo_db.sqlalchemy.engines     context)
Jan 02 14:20:07 jfz1r03h11 devstack@placement-api.service[14363]: ERROR oslo_db.sqlalchemy.engines   File "/usr/local/lib/python2.7/dist-packages/sqlalchemy/engine/default.py", line 509, in do_execute
Jan 02 14:20:07 jfz1r03h11 devstack@placement-api.service[14363]: ERROR oslo_db.sqlalchemy.engines     cursor.execute(statement, parameters)
Jan 02 14:20:07 jfz1r03h11 devstack@placement-api.service[14363]: ERROR oslo_db.sqlalchemy.engines   File "/usr/local/lib/python2.7/dist-packages/pymysql/cursors.py", line 170, in execute
Jan 02 14:20:07 jfz1r03h11 devstack@placement-api.service[14363]: ERROR oslo_db.sqlalchemy.engines     result = self._query(query)
Jan 02 14:20:07 jfz1r03h11 devstack@placement-api.service[14363]: ERROR oslo_db.sqlalchemy.engines   File "/usr/local/lib/python2.7/dist-packages/pymysql/cursors.py", line 328, in _query
Jan 02 14:20:07 jfz1r03h11 devstack@placement-api.service[14363]: ERROR oslo_db.sqlalchemy.engines     conn.query(q)
Jan 02 14:20:07 jfz1r03h11 devstack@placement-api.service[14363]: ERROR oslo_db.sqlalchemy.engines   File "/usr/local/lib/python2.7/dist-packages/pymysql/connections.py", line 517, in query
Jan 02 14:20:07 jfz1r03h11 devstack@placement-api.service[14363]: ERROR oslo_db.sqlalchemy.engines     self._affected_rows = self._read_query_result(unbuffered=unbuffered)
Jan 02 14:20:07 jfz1r03h11 devstack@placement-api.service[14363]: ERROR oslo_db.sqlalchemy.engines   File "/usr/local/lib/python2.7/dist-packages/pymysql/connections.py", line 732, in _read_query_result
Jan 02 14:20:07 jfz1r03h11 devstack@placement-api.service[14363]: ERROR oslo_db.sqlalchemy.engines     result.read()
Jan 02 14:20:07 jfz1r03h11 devstack@placement-api.service[14363]: ERROR oslo_db.sqlalchemy.engines   File "/usr/local/lib/python2.7/dist-packages/pymysql/connections.py", line 1075, in read
Jan 02 14:20:07 jfz1r03h11 devstack@placement-api.service[14363]: ERROR oslo_db.sqlalchemy.engines     first_packet = self.connection._read_packet()
Jan 02 14:20:07 jfz1r03h11 devstack@placement-api.service[14363]: ERROR oslo_db.sqlalchemy.engines   File "/usr/local/lib/python2.7/dist-packages/pymysql/connections.py", line 657, in _read_packet
Jan 02 14:20:07 jfz1r03h11 devstack@placement-api.service[14363]: ERROR oslo_db.sqlalchemy.engines     packet_header = self._read_bytes(4)
Jan 02 14:20:07 jfz1r03h11 devstack@placement-api.service[14363]: ERROR oslo_db.sqlalchemy.engines   File "/usr/local/lib/python2.7/dist-packages/pymysql/connections.py", line 707, in _read_bytes
Jan 02 14:20:07 jfz1r03h11 devstack@placement-api.service[14363]: ERROR oslo_db.sqlalchemy.engines     CR.CR_SERVER_LOST, "Lost connection to MySQL server during query")
Jan 02 14:20:07 jfz1r03h11 devstack@placement-api.service[14363]: ERROR oslo_db.sqlalchemy.engines DBConnectionError: (pymysql.err.OperationalError) (2013, 'Lost connection to MySQL server during query') [SQL: u'SELECT 1'] (Background on this error at: http://sqlalche.me/e/e3q8)
Jan 02 14:20:07 jfz1r03h11 devstack@placement-api.service[14363]: ERROR oslo_db.sqlalchemy.engines 
Jan 02 14:20:07 jfz1r03h11 devstack@placement-api.service[14363]: INFO placement.requestlog [req-6ba7aad8-997a-4851-ae1a-6f60f088f466 req-21e651e2-efce-41d9-939d-94efc219836e service placement] 172.16.3.11 "GET /placement/resource_providers?in_tree=39144ddc-c0a4-4deb-9436-7903c9f298ca" status: 200 len: 26 microversion: 1.14
Jan 02 14:20:07 jfz1r03h11 devstack@placement-api.service[14363]: [pid: 14374|app: 0|req: 32/542] 172.16.3.11 () {64 vars in 1451 bytes} [Wed Jan  2 14:20:07 2019] GET /placement/resource_providers?in_tree=39144ddc-c0a4-4deb-9436-7903c9f298ca => generated 26 bytes in 178 msecs (HTTP/1.1 200) 6 headers in 224 bytes (1 switches on core 0)
Jan 02 14:20:07 jfz1r03h11 devstack@placement-api.service[14363]: DEBUG placement.requestlog [req-6ba7aad8-997a-4851-ae1a-6f60f088f466 req-539fea2f-93c3-477c-9161-9d1f9aa6f76f service placement] Starting request: 172.16.3.11 "POST /placement/resource_providers" {{(pid=14385) __call__ /opt/stack/placement/placement/requestlog.py:38}}
Jan 02 14:20:07 jfz1r03h11 devstack@placement-api.service[14363]: ERROR oslo_db.sqlalchemy.engines [req-6ba7aad8-997a-4851-ae1a-6f60f088f466 req-539fea2f-93c3-477c-9161-9d1f9aa6f76f service placement] Database connection was found disconnected; reconnecting: DBConnectionError: (pymysql.err.OperationalError) (2013, 'Lost connection to MySQL server during query') [SQL: u'SELECT 1'] (Background on this error at: http://sqlalche.me/e/e3q8)
Jan 02 14:20:07 jfz1r03h11 devstack@placement-api.service[14363]: ERROR oslo_db.sqlalchemy.engines Traceback (most recent call last):
Jan 02 14:20:07 jfz1r03h11 devstack@placement-api.service[14363]: ERROR oslo_db.sqlalchemy.engines   File "/usr/local/lib/python2.7/dist-packages/oslo_db/sqlalchemy/engines.py", line 73, in _connect_ping_listener
Jan 02 14:20:07 jfz1r03h11 devstack@placement-api.service[14363]: ERROR oslo_db.sqlalchemy.engines     connection.scalar(select([1]))
Jan 02 14:20:07 jfz1r03h11 devstack@placement-api.service[14363]: ERROR oslo_db.sqlalchemy.engines   File "/usr/local/lib/python2.7/dist-packages/sqlalchemy/engine/base.py", line 880, in scalar
Jan 02 14:20:07 jfz1r03h11 devstack@placement-api.service[14363]: ERROR oslo_db.sqlalchemy.engines     return self.execute(object, *multiparams, **params).scalar()
Jan 02 14:20:07 jfz1r03h11 devstack@placement-api.service[14363]: ERROR oslo_db.sqlalchemy.engines   File "/usr/local/lib/python2.7/dist-packages/sqlalchemy/engine/base.py", line 948, in execute
Jan 02 14:20:07 jfz1r03h11 devstack@placement-api.service[14363]: ERROR oslo_db.sqlalchemy.engines     return meth(self, multiparams, params)
Jan 02 14:20:07 jfz1r03h11 devstack@placement-api.service[14363]: ERROR oslo_db.sqlalchemy.engines   File "/usr/local/lib/python2.7/dist-packages/sqlalchemy/sql/elements.py", line 269, in _execute_on_connection
Jan 02 14:20:07 jfz1r03h11 devstack@placement-api.service[14363]: ERROR oslo_db.sqlalchemy.engines     return connection._execute_clauseelement(self, multiparams, params)
Jan 02 14:20:07 jfz1r03h11 devstack@placement-api.service[14363]: ERROR oslo_db.sqlalchemy.engines   File "/usr/local/lib/python2.7/dist-packages/sqlalchemy/engine/base.py", line 1060, in _execute_clauseelement
Jan 02 14:20:07 jfz1r03h11 devstack@placement-api.service[14363]: ERROR oslo_db.sqlalchemy.engines     compiled_sql, distilled_params
Jan 02 14:20:07 jfz1r03h11 devstack@placement-api.service[14363]: ERROR oslo_db.sqlalchemy.engines   File "/usr/local/lib/python2.7/dist-packages/sqlalchemy/engine/base.py", line 1200, in _execute_context
Jan 02 14:20:07 jfz1r03h11 devstack@placement-api.service[14363]: ERROR oslo_db.sqlalchemy.engines     context)
Jan 02 14:20:07 jfz1r03h11 devstack@placement-api.service[14363]: ERROR oslo_db.sqlalchemy.engines   File "/usr/local/lib/python2.7/dist-packages/sqlalchemy/engine/base.py", line 1409, in _handle_dbapi_exception
Jan 02 14:20:07 jfz1r03h11 devstack@placement-api.service[14363]: ERROR oslo_db.sqlalchemy.engines     util.raise_from_cause(newraise, exc_info)
Jan 02 14:20:07 jfz1r03h11 devstack@placement-api.service[14363]: ERROR oslo_db.sqlalchemy.engines   File "/usr/local/lib/python2.7/dist-packages/sqlalchemy/util/compat.py", line 265, in raise_from_cause
Jan 02 14:20:07 jfz1r03h11 devstack@placement-api.service[14363]: ERROR oslo_db.sqlalchemy.engines     reraise(type(exception), exception, tb=exc_tb, cause=cause)
Jan 02 14:20:07 jfz1r03h11 devstack@placement-api.service[14363]: ERROR oslo_db.sqlalchemy.engines   File "/usr/local/lib/python2.7/dist-packages/sqlalchemy/engine/base.py", line 1193, in _execute_context
Jan 02 14:20:07 jfz1r03h11 devstack@placement-api.service[14363]: ERROR oslo_db.sqlalchemy.engines     context)
Jan 02 14:20:07 jfz1r03h11 devstack@placement-api.service[14363]: ERROR oslo_db.sqlalchemy.engines   File "/usr/local/lib/python2.7/dist-packages/sqlalchemy/engine/default.py", line 509, in do_execute
Jan 02 14:20:07 jfz1r03h11 devstack@placement-api.service[14363]: ERROR oslo_db.sqlalchemy.engines     cursor.execute(statement, parameters)
Jan 02 14:20:07 jfz1r03h11 devstack@placement-api.service[14363]: ERROR oslo_db.sqlalchemy.engines   File "/usr/local/lib/python2.7/dist-packages/pymysql/cursors.py", line 170, in execute
Jan 02 14:20:07 jfz1r03h11 devstack@placement-api.service[14363]: ERROR oslo_db.sqlalchemy.engines     result = self._query(query)
Jan 02 14:20:07 jfz1r03h11 devstack@placement-api.service[14363]: ERROR oslo_db.sqlalchemy.engines   File "/usr/local/lib/python2.7/dist-packages/pymysql/cursors.py", line 328, in _query
Jan 02 14:20:07 jfz1r03h11 devstack@placement-api.service[14363]: ERROR oslo_db.sqlalchemy.engines     conn.query(q)
Jan 02 14:20:07 jfz1r03h11 devstack@placement-api.service[14363]: ERROR oslo_db.sqlalchemy.engines   File "/usr/local/lib/python2.7/dist-packages/pymysql/connections.py", line 517, in query
Jan 02 14:20:07 jfz1r03h11 devstack@placement-api.service[14363]: ERROR oslo_db.sqlalchemy.engines     self._affected_rows = self._read_query_result(unbuffered=unbuffered)
Jan 02 14:20:07 jfz1r03h11 devstack@placement-api.service[14363]: ERROR oslo_db.sqlalchemy.engines   File "/usr/local/lib/python2.7/dist-packages/pymysql/connections.py", line 732, in _read_query_result
Jan 02 14:20:07 jfz1r03h11 devstack@placement-api.service[14363]: ERROR oslo_db.sqlalchemy.engines     result.read()
Jan 02 14:20:07 jfz1r03h11 devstack@placement-api.service[14363]: ERROR oslo_db.sqlalchemy.engines   File "/usr/local/lib/python2.7/dist-packages/pymysql/connections.py", line 1075, in read
Jan 02 14:20:07 jfz1r03h11 devstack@placement-api.service[14363]: ERROR oslo_db.sqlalchemy.engines     first_packet = self.connection._read_packet()
Jan 02 14:20:07 jfz1r03h11 devstack@placement-api.service[14363]: ERROR oslo_db.sqlalchemy.engines   File "/usr/local/lib/python2.7/dist-packages/pymysql/connections.py", line 657, in _read_packet
Jan 02 14:20:07 jfz1r03h11 devstack@placement-api.service[14363]: ERROR oslo_db.sqlalchemy.engines     packet_header = self._read_bytes(4)
Jan 02 14:20:07 jfz1r03h11 devstack@placement-api.service[14363]: ERROR oslo_db.sqlalchemy.engines   File "/usr/local/lib/python2.7/dist-packages/pymysql/connections.py", line 707, in _read_bytes
Jan 02 14:20:07 jfz1r03h11 devstack@placement-api.service[14363]: ERROR oslo_db.sqlalchemy.engines     CR.CR_SERVER_LOST, "Lost connection to MySQL server during query")
Jan 02 14:20:07 jfz1r03h11 devstack@placement-api.service[14363]: ERROR oslo_db.sqlalchemy.engines DBConnectionError: (pymysql.err.OperationalError) (2013, 'Lost connection to MySQL server during query') [SQL: u'SELECT 1'] (Background on this error at: http://sqlalche.me/e/e3q8)
Jan 02 14:20:07 jfz1r03h11 devstack@placement-api.service[14363]: ERROR oslo_db.sqlalchemy.engines 
Jan 02 14:20:07 jfz1r03h11 devstack@placement-api.service[14363]: INFO placement.requestlog [req-6ba7aad8-997a-4851-ae1a-6f60f088f466 req-539fea2f-93c3-477c-9161-9d1f9aa6f76f service placement] 172.16.3.11 "POST /placement/resource_providers" status: 200 len: 833 microversion: 1.20
Jan 02 14:20:07 jfz1r03h11 devstack@placement-api.service[14363]: [pid: 14385|app: 0|req: 31/543] 172.16.3.11 () {68 vars in 1415 bytes} [Wed Jan  2 14:20:07 2019] POST /placement/resource_providers => generated 833 bytes in 147 msecs (HTTP/1.1 200) 9 headers in 392 bytes (1 switches on core 0)
Jan 02 14:20:08 jfz1r03h11 devstack@placement-api.service[14363]: DEBUG placement.requestlog [req-6ba7aad8-997a-4851-ae1a-6f60f088f466 req-87fc4d2f-73f6-41a7-ba70-32df6253ad4b service placement] Starting request: 172.16.3.11 "GET /placement/resource_providers/39144ddc-c0a4-4deb-9436-7903c9f298ca/inventories" {{(pid=14380) __call__ /opt/stack/placement/placement/requestlog.py:38}}
Jan 02 14:20:08 jfz1r03h11 devstack@placement-api.service[14363]: ERROR oslo_db.sqlalchemy.engines [req-6ba7aad8-997a-4851-ae1a-6f60f088f466 req-87fc4d2f-73f6-41a7-ba70-32df6253ad4b service placement] Database connection was found disconnected; reconnecting: DBConnectionError: (pymysql.err.OperationalError) (2013, 'Lost connection to MySQL server during query') [SQL: u'SELECT 1'] (Background on this error at: http://sqlalche.me/e/e3q8)
Jan 02 14:20:08 jfz1r03h11 devstack@placement-api.service[14363]: ERROR oslo_db.sqlalchemy.engines Traceback (most recent call last):
Jan 02 14:20:08 jfz1r03h11 devstack@placement-api.service[14363]: ERROR oslo_db.sqlalchemy.engines   File "/usr/local/lib/python2.7/dist-packages/oslo_db/sqlalchemy/engines.py", line 73, in _connect_ping_listener
Jan 02 14:20:08 jfz1r03h11 devstack@placement-api.service[14363]: ERROR oslo_db.sqlalchemy.engines     connection.scalar(select([1]))
Jan 02 14:20:08 jfz1r03h11 devstack@placement-api.service[14363]: ERROR oslo_db.sqlalchemy.engines   File "/usr/local/lib/python2.7/dist-packages/sqlalchemy/engine/base.py", line 880, in scalar
Jan 02 14:20:08 jfz1r03h11 devstack@placement-api.service[14363]: ERROR oslo_db.sqlalchemy.engines     return self.execute(object, *multiparams, **params).scalar()
Jan 02 14:20:08 jfz1r03h11 devstack@placement-api.service[14363]: ERROR oslo_db.sqlalchemy.engines   File "/usr/local/lib/python2.7/dist-packages/sqlalchemy/engine/base.py", line 948, in execute
Jan 02 14:20:08 jfz1r03h11 devstack@placement-api.service[14363]: ERROR oslo_db.sqlalchemy.engines     return meth(self, multiparams, params)
Jan 02 14:20:08 jfz1r03h11 devstack@placement-api.service[14363]: ERROR oslo_db.sqlalchemy.engines   File "/usr/local/lib/python2.7/dist-packages/sqlalchemy/sql/elements.py", line 269, in _execute_on_connection
Jan 02 14:20:08 jfz1r03h11 devstack@placement-api.service[14363]: ERROR oslo_db.sqlalchemy.engines     return connection._execute_clauseelement(self, multiparams, params)
Jan 02 14:20:08 jfz1r03h11 devstack@placement-api.service[14363]: ERROR oslo_db.sqlalchemy.engines   File "/usr/local/lib/python2.7/dist-packages/sqlalchemy/engine/base.py", line 1060, in _execute_clauseelement
Jan 02 14:20:08 jfz1r03h11 devstack@placement-api.service[14363]: ERROR oslo_db.sqlalchemy.engines     compiled_sql, distilled_params
Jan 02 14:20:08 jfz1r03h11 devstack@placement-api.service[14363]: ERROR oslo_db.sqlalchemy.engines   File "/usr/local/lib/python2.7/dist-packages/sqlalchemy/engine/base.py", line 1200, in _execute_context
Jan 02 14:20:08 jfz1r03h11 devstack@placement-api.service[14363]: ERROR oslo_db.sqlalchemy.engines     context)
Jan 02 14:20:08 jfz1r03h11 devstack@placement-api.service[14363]: ERROR oslo_db.sqlalchemy.engines   File "/usr/local/lib/python2.7/dist-packages/sqlalchemy/engine/base.py", line 1409, in _handle_dbapi_exception
Jan 02 14:20:08 jfz1r03h11 devstack@placement-api.service[14363]: ERROR oslo_db.sqlalchemy.engines     util.raise_from_cause(newraise, exc_info)
Jan 02 14:20:08 jfz1r03h11 devstack@placement-api.service[14363]: ERROR oslo_db.sqlalchemy.engines   File "/usr/local/lib/python2.7/dist-packages/sqlalchemy/util/compat.py", line 265, in raise_from_cause
Jan 02 14:20:08 jfz1r03h11 devstack@placement-api.service[14363]: ERROR oslo_db.sqlalchemy.engines     reraise(type(exception), exception, tb=exc_tb, cause=cause)
Jan 02 14:20:08 jfz1r03h11 devstack@placement-api.service[14363]: ERROR oslo_db.sqlalchemy.engines   File "/usr/local/lib/python2.7/dist-packages/sqlalchemy/engine/base.py", line 1193, in _execute_context
Jan 02 14:20:08 jfz1r03h11 devstack@placement-api.service[14363]: ERROR oslo_db.sqlalchemy.engines     context)
Jan 02 14:20:08 jfz1r03h11 devstack@placement-api.service[14363]: ERROR oslo_db.sqlalchemy.engines   File "/usr/local/lib/python2.7/dist-packages/sqlalchemy/engine/default.py", line 509, in do_execute
Jan 02 14:20:08 jfz1r03h11 devstack@placement-api.service[14363]: ERROR oslo_db.sqlalchemy.engines     cursor.execute(statement, parameters)
Jan 02 14:20:08 jfz1r03h11 devstack@placement-api.service[14363]: ERROR oslo_db.sqlalchemy.engines   File "/usr/local/lib/python2.7/dist-packages/pymysql/cursors.py", line 170, in execute
Jan 02 14:20:08 jfz1r03h11 devstack@placement-api.service[14363]: ERROR oslo_db.sqlalchemy.engines     result = self._query(query)
Jan 02 14:20:08 jfz1r03h11 devstack@placement-api.service[14363]: ERROR oslo_db.sqlalchemy.engines   File "/usr/local/lib/python2.7/dist-packages/pymysql/cursors.py", line 328, in _query
Jan 02 14:20:08 jfz1r03h11 devstack@placement-api.service[14363]: ERROR oslo_db.sqlalchemy.engines     conn.query(q)
Jan 02 14:20:08 jfz1r03h11 devstack@placement-api.service[14363]: ERROR oslo_db.sqlalchemy.engines   File "/usr/local/lib/python2.7/dist-packages/pymysql/connections.py", line 517, in query
Jan 02 14:20:08 jfz1r03h11 devstack@placement-api.service[14363]: ERROR oslo_db.sqlalchemy.engines     self._affected_rows = self._read_query_result(unbuffered=unbuffered)
Jan 02 14:20:08 jfz1r03h11 devstack@placement-api.service[14363]: ERROR oslo_db.sqlalchemy.engines   File "/usr/local/lib/python2.7/dist-packages/pymysql/connections.py", line 732, in _read_query_result
Jan 02 14:20:08 jfz1r03h11 devstack@placement-api.service[14363]: ERROR oslo_db.sqlalchemy.engines     result.read()
Jan 02 14:20:08 jfz1r03h11 devstack@placement-api.service[14363]: ERROR oslo_db.sqlalchemy.engines   File "/usr/local/lib/python2.7/dist-packages/pymysql/connections.py", line 1075, in read
Jan 02 14:20:08 jfz1r03h11 devstack@placement-api.service[14363]: ERROR oslo_db.sqlalchemy.engines     first_packet = self.connection._read_packet()
Jan 02 14:20:08 jfz1r03h11 devstack@placement-api.service[14363]: ERROR oslo_db.sqlalchemy.engines   File "/usr/local/lib/python2.7/dist-packages/pymysql/connections.py", line 657, in _read_packet
Jan 02 14:20:08 jfz1r03h11 devstack@placement-api.service[14363]: ERROR oslo_db.sqlalchemy.engines     packet_header = self._read_bytes(4)
Jan 02 14:20:08 jfz1r03h11 devstack@placement-api.service[14363]: ERROR oslo_db.sqlalchemy.engines   File "/usr/local/lib/python2.7/dist-packages/pymysql/connections.py", line 707, in _read_bytes
Jan 02 14:20:08 jfz1r03h11 devstack@placement-api.service[14363]: ERROR oslo_db.sqlalchemy.engines     CR.CR_SERVER_LOST, "Lost connection to MySQL server during query")
Jan 02 14:20:08 jfz1r03h11 devstack@placement-api.service[14363]: ERROR oslo_db.sqlalchemy.engines DBConnectionError: (pymysql.err.OperationalError) (2013, 'Lost connection to MySQL server during query') [SQL: u'SELECT 1'] (Background on this error at: http://sqlalche.me/e/e3q8)
Jan 02 14:20:08 jfz1r03h11 devstack@placement-api.service[14363]: ERROR oslo_db.sqlalchemy.engines 
Jan 02 14:20:08 jfz1r03h11 devstack@placement-api.service[14363]: INFO placement.requestlog [req-6ba7aad8-997a-4851-ae1a-6f60f088f466 req-87fc4d2f-73f6-41a7-ba70-32df6253ad4b service placement] 172.16.3.11 "GET /placement/resource_providers/39144ddc-c0a4-4deb-9436-7903c9f298ca/inventories" status: 200 len: 54 microversion: 1.0
Jan 02 14:20:08 jfz1r03h11 devstack@placement-api.service[14363]: [pid: 14380|app: 0|req: 31/544] 172.16.3.11 () {62 vars in 1465 bytes} [Wed Jan  2 14:20:07 2019] GET /placement/resource_providers/39144ddc-c0a4-4deb-9436-7903c9f298ca/inventories => generated 54 bytes in 180 msecs (HTTP/1.1 200) 6 headers in 223 bytes (1 switches on core 0)
Jan 02 14:20:08 jfz1r03h11 devstack@placement-api.service[14363]: DEBUG placement.requestlog [req-6ba7aad8-997a-4851-ae1a-6f60f088f466 req-02e1d62d-e10c-420a-a665-1ecd4db28530 service placement] Starting request: 172.16.3.11 "PUT /placement/resource_providers/39144ddc-c0a4-4deb-9436-7903c9f298ca/inventories" {{(pid=14381) __call__ /opt/stack/placement/placement/requestlog.py:38}}
Jan 02 14:20:08 jfz1r03h11 devstack@placement-api.service[14363]: ERROR oslo_db.sqlalchemy.engines [req-6ba7aad8-997a-4851-ae1a-6f60f088f466 req-02e1d62d-e10c-420a-a665-1ecd4db28530 service placement] Database connection was found disconnected; reconnecting: DBConnectionError: (pymysql.err.OperationalError) (2013, 'Lost connection to MySQL server during query') [SQL: u'SELECT 1'] (Background on this error at: http://sqlalche.me/e/e3q8)
Jan 02 14:20:08 jfz1r03h11 devstack@placement-api.service[14363]: ERROR oslo_db.sqlalchemy.engines Traceback (most recent call last):
Jan 02 14:20:08 jfz1r03h11 devstack@placement-api.service[14363]: ERROR oslo_db.sqlalchemy.engines   File "/usr/local/lib/python2.7/dist-packages/oslo_db/sqlalchemy/engines.py", line 73, in _connect_ping_listener
Jan 02 14:20:08 jfz1r03h11 devstack@placement-api.service[14363]: ERROR oslo_db.sqlalchemy.engines     connection.scalar(select([1]))
Jan 02 14:20:08 jfz1r03h11 devstack@placement-api.service[14363]: ERROR oslo_db.sqlalchemy.engines   File "/usr/local/lib/python2.7/dist-packages/sqlalchemy/engine/base.py", line 880, in scalar
Jan 02 14:20:08 jfz1r03h11 devstack@placement-api.service[14363]: ERROR oslo_db.sqlalchemy.engines     return self.execute(object, *multiparams, **params).scalar()
Jan 02 14:20:08 jfz1r03h11 devstack@placement-api.service[14363]: ERROR oslo_db.sqlalchemy.engines   File "/usr/local/lib/python2.7/dist-packages/sqlalchemy/engine/base.py", line 948, in execute
Jan 02 14:20:08 jfz1r03h11 devstack@placement-api.service[14363]: ERROR oslo_db.sqlalchemy.engines     return meth(self, multiparams, params)
Jan 02 14:20:08 jfz1r03h11 devstack@placement-api.service[14363]: ERROR oslo_db.sqlalchemy.engines   File "/usr/local/lib/python2.7/dist-packages/sqlalchemy/sql/elements.py", line 269, in _execute_on_connection
Jan 02 14:20:08 jfz1r03h11 devstack@placement-api.service[14363]: ERROR oslo_db.sqlalchemy.engines     return connection._execute_clauseelement(self, multiparams, params)
Jan 02 14:20:08 jfz1r03h11 devstack@placement-api.service[14363]: ERROR oslo_db.sqlalchemy.engines   File "/usr/local/lib/python2.7/dist-packages/sqlalchemy/engine/base.py", line 1060, in _execute_clauseelement
Jan 02 14:20:08 jfz1r03h11 devstack@placement-api.service[14363]: ERROR oslo_db.sqlalchemy.engines     compiled_sql, distilled_params
Jan 02 14:20:08 jfz1r03h11 devstack@placement-api.service[14363]: ERROR oslo_db.sqlalchemy.engines   File "/usr/local/lib/python2.7/dist-packages/sqlalchemy/engine/base.py", line 1200, in _execute_context
Jan 02 14:20:08 jfz1r03h11 devstack@placement-api.service[14363]: ERROR oslo_db.sqlalchemy.engines     context)
Jan 02 14:20:08 jfz1r03h11 devstack@placement-api.service[14363]: ERROR oslo_db.sqlalchemy.engines   File "/usr/local/lib/python2.7/dist-packages/sqlalchemy/engine/base.py", line 1409, in _handle_dbapi_exception
Jan 02 14:20:08 jfz1r03h11 devstack@placement-api.service[14363]: ERROR oslo_db.sqlalchemy.engines     util.raise_from_cause(newraise, exc_info)
Jan 02 14:20:08 jfz1r03h11 devstack@placement-api.service[14363]: ERROR oslo_db.sqlalchemy.engines   File "/usr/local/lib/python2.7/dist-packages/sqlalchemy/util/compat.py", line 265, in raise_from_cause
Jan 02 14:20:08 jfz1r03h11 devstack@placement-api.service[14363]: ERROR oslo_db.sqlalchemy.engines     reraise(type(exception), exception, tb=exc_tb, cause=cause)
Jan 02 14:20:08 jfz1r03h11 devstack@placement-api.service[14363]: ERROR oslo_db.sqlalchemy.engines   File "/usr/local/lib/python2.7/dist-packages/sqlalchemy/engine/base.py", line 1193, in _execute_context
Jan 02 14:20:08 jfz1r03h11 devstack@placement-api.service[14363]: ERROR oslo_db.sqlalchemy.engines     context)
Jan 02 14:20:08 jfz1r03h11 devstack@placement-api.service[14363]: ERROR oslo_db.sqlalchemy.engines   File "/usr/local/lib/python2.7/dist-packages/sqlalchemy/engine/default.py", line 509, in do_execute
Jan 02 14:20:08 jfz1r03h11 devstack@placement-api.service[14363]: ERROR oslo_db.sqlalchemy.engines     cursor.execute(statement, parameters)
Jan 02 14:20:08 jfz1r03h11 devstack@placement-api.service[14363]: ERROR oslo_db.sqlalchemy.engines   File "/usr/local/lib/python2.7/dist-packages/pymysql/cursors.py", line 170, in execute
Jan 02 14:20:08 jfz1r03h11 devstack@placement-api.service[14363]: ERROR oslo_db.sqlalchemy.engines     result = self._query(query)
Jan 02 14:20:08 jfz1r03h11 devstack@placement-api.service[14363]: ERROR oslo_db.sqlalchemy.engines   File "/usr/local/lib/python2.7/dist-packages/pymysql/cursors.py", line 328, in _query
Jan 02 14:20:08 jfz1r03h11 devstack@placement-api.service[14363]: ERROR oslo_db.sqlalchemy.engines     conn.query(q)
Jan 02 14:20:08 jfz1r03h11 devstack@placement-api.service[14363]: ERROR oslo_db.sqlalchemy.engines   File "/usr/local/lib/python2.7/dist-packages/pymysql/connections.py", line 517, in query
Jan 02 14:20:08 jfz1r03h11 devstack@placement-api.service[14363]: ERROR oslo_db.sqlalchemy.engines     self._affected_rows = self._read_query_result(unbuffered=unbuffered)
Jan 02 14:20:08 jfz1r03h11 devstack@placement-api.service[14363]: ERROR oslo_db.sqlalchemy.engines   File "/usr/local/lib/python2.7/dist-packages/pymysql/connections.py", line 732, in _read_query_result
Jan 02 14:20:08 jfz1r03h11 devstack@placement-api.service[14363]: ERROR oslo_db.sqlalchemy.engines     result.read()
Jan 02 14:20:08 jfz1r03h11 devstack@placement-api.service[14363]: ERROR oslo_db.sqlalchemy.engines   File "/usr/local/lib/python2.7/dist-packages/pymysql/connections.py", line 1075, in read
Jan 02 14:20:08 jfz1r03h11 devstack@placement-api.service[14363]: ERROR oslo_db.sqlalchemy.engines     first_packet = self.connection._read_packet()
Jan 02 14:20:08 jfz1r03h11 devstack@placement-api.service[14363]: ERROR oslo_db.sqlalchemy.engines   File "/usr/local/lib/python2.7/dist-packages/pymysql/connections.py", line 657, in _read_packet
Jan 02 14:20:08 jfz1r03h11 devstack@placement-api.service[14363]: ERROR oslo_db.sqlalchemy.engines     packet_header = self._read_bytes(4)
Jan 02 14:20:08 jfz1r03h11 devstack@placement-api.service[14363]: ERROR oslo_db.sqlalchemy.engines   File "/usr/local/lib/python2.7/dist-packages/pymysql/connections.py", line 707, in _read_bytes
Jan 02 14:20:08 jfz1r03h11 devstack@placement-api.service[14363]: ERROR oslo_db.sqlalchemy.engines     CR.CR_SERVER_LOST, "Lost connection to MySQL server during query")
Jan 02 14:20:08 jfz1r03h11 devstack@placement-api.service[14363]: ERROR oslo_db.sqlalchemy.engines DBConnectionError: (pymysql.err.OperationalError) (2013, 'Lost connection to MySQL server during query') [SQL: u'SELECT 1'] (Background on this error at: http://sqlalche.me/e/e3q8)
Jan 02 14:20:08 jfz1r03h11 devstack@placement-api.service[14363]: ERROR oslo_db.sqlalchemy.engines 
Jan 02 14:20:08 jfz1r03h11 devstack@placement-api.service[14363]: INFO placement.requestlog [req-6ba7aad8-997a-4851-ae1a-6f60f088f466 req-02e1d62d-e10c-420a-a665-1ecd4db28530 service placement] 172.16.3.11 "PUT /placement/resource_providers/39144ddc-c0a4-4deb-9436-7903c9f298ca/inventories" status: 200 len: 403 microversion: 1.26
Jan 02 14:20:08 jfz1r03h11 devstack@placement-api.service[14363]: [pid: 14381|app: 0|req: 31/545] 172.16.3.11 () {68 vars in 1562 bytes} [Wed Jan  2 14:20:08 2019] PUT /placement/resource_providers/39144ddc-c0a4-4deb-9436-7903c9f298ca/inventories => generated 403 bytes in 171 msecs (HTTP/1.1 200) 8 headers in 296 bytes (1 switches on core 0)
Jan 02 14:20:08 jfz1r03h11 devstack@placement-api.service[14363]: DEBUG placement.requestlog [req-6ba7aad8-997a-4851-ae1a-6f60f088f466 req-a7a2f62d-233c-403e-8ccc-b7e49c7a60f8 service placement] Starting request: 172.16.3.11 "GET /placement/traits?name=in:HW_CPU_X86_SSE2,HW_CPU_X86_SSE,HW_CPU_X86_SVM,HW_CPU_X86_MMX" {{(pid=14376) __call__ /opt/stack/placement/placement/requestlog.py:38}}
Jan 02 14:20:08 jfz1r03h11 devstack@placement-api.service[14363]: ERROR oslo_db.sqlalchemy.engines [req-6ba7aad8-997a-4851-ae1a-6f60f088f466 req-a7a2f62d-233c-403e-8ccc-b7e49c7a60f8 service placement] Database connection was found disconnected; reconnecting: DBConnectionError: (pymysql.err.OperationalError) (2013, 'Lost connection to MySQL server during query') [SQL: u'SELECT 1'] (Background on this error at: http://sqlalche.me/e/e3q8)
Jan 02 14:20:08 jfz1r03h11 devstack@placement-api.service[14363]: ERROR oslo_db.sqlalchemy.engines Traceback (most recent call last):
Jan 02 14:20:08 jfz1r03h11 devstack@placement-api.service[14363]: ERROR oslo_db.sqlalchemy.engines   File "/usr/local/lib/python2.7/dist-packages/oslo_db/sqlalchemy/engines.py", line 73, in _connect_ping_listener
Jan 02 14:20:08 jfz1r03h11 devstack@placement-api.service[14363]: ERROR oslo_db.sqlalchemy.engines     connection.scalar(select([1]))
Jan 02 14:20:08 jfz1r03h11 devstack@placement-api.service[14363]: ERROR oslo_db.sqlalchemy.engines   File "/usr/local/lib/python2.7/dist-packages/sqlalchemy/engine/base.py", line 880, in scalar
Jan 02 14:20:08 jfz1r03h11 devstack@placement-api.service[14363]: ERROR oslo_db.sqlalchemy.engines     return self.execute(object, *multiparams, **params).scalar()
Jan 02 14:20:08 jfz1r03h11 devstack@placement-api.service[14363]: ERROR oslo_db.sqlalchemy.engines   File "/usr/local/lib/python2.7/dist-packages/sqlalchemy/engine/base.py", line 948, in execute
Jan 02 14:20:08 jfz1r03h11 devstack@placement-api.service[14363]: ERROR oslo_db.sqlalchemy.engines     return meth(self, multiparams, params)
Jan 02 14:20:08 jfz1r03h11 devstack@placement-api.service[14363]: ERROR oslo_db.sqlalchemy.engines   File "/usr/local/lib/python2.7/dist-packages/sqlalchemy/sql/elements.py", line 269, in _execute_on_connection
Jan 02 14:20:08 jfz1r03h11 devstack@placement-api.service[14363]: ERROR oslo_db.sqlalchemy.engines     return connection._execute_clauseelement(self, multiparams, params)
Jan 02 14:20:08 jfz1r03h11 devstack@placement-api.service[14363]: ERROR oslo_db.sqlalchemy.engines   File "/usr/local/lib/python2.7/dist-packages/sqlalchemy/engine/base.py", line 1060, in _execute_clauseelement
Jan 02 14:20:08 jfz1r03h11 devstack@placement-api.service[14363]: ERROR oslo_db.sqlalchemy.engines     compiled_sql, distilled_params
Jan 02 14:20:08 jfz1r03h11 devstack@placement-api.service[14363]: ERROR oslo_db.sqlalchemy.engines   File "/usr/local/lib/python2.7/dist-packages/sqlalchemy/engine/base.py", line 1200, in _execute_context
Jan 02 14:20:08 jfz1r03h11 devstack@placement-api.service[14363]: ERROR oslo_db.sqlalchemy.engines     context)
Jan 02 14:20:08 jfz1r03h11 devstack@placement-api.service[14363]: ERROR oslo_db.sqlalchemy.engines   File "/usr/local/lib/python2.7/dist-packages/sqlalchemy/engine/base.py", line 1409, in _handle_dbapi_exception
Jan 02 14:20:08 jfz1r03h11 devstack@placement-api.service[14363]: ERROR oslo_db.sqlalchemy.engines     util.raise_from_cause(newraise, exc_info)
Jan 02 14:20:08 jfz1r03h11 devstack@placement-api.service[14363]: ERROR oslo_db.sqlalchemy.engines   File "/usr/local/lib/python2.7/dist-packages/sqlalchemy/util/compat.py", line 265, in raise_from_cause
Jan 02 14:20:08 jfz1r03h11 devstack@placement-api.service[14363]: ERROR oslo_db.sqlalchemy.engines     reraise(type(exception), exception, tb=exc_tb, cause=cause)
Jan 02 14:20:08 jfz1r03h11 devstack@placement-api.service[14363]: ERROR oslo_db.sqlalchemy.engines   File "/usr/local/lib/python2.7/dist-packages/sqlalchemy/engine/base.py", line 1193, in _execute_context
Jan 02 14:20:08 jfz1r03h11 devstack@placement-api.service[14363]: ERROR oslo_db.sqlalchemy.engines     context)
Jan 02 14:20:08 jfz1r03h11 devstack@placement-api.service[14363]: ERROR oslo_db.sqlalchemy.engines   File "/usr/local/lib/python2.7/dist-packages/sqlalchemy/engine/default.py", line 509, in do_execute
Jan 02 14:20:08 jfz1r03h11 devstack@placement-api.service[14363]: ERROR oslo_db.sqlalchemy.engines     cursor.execute(statement, parameters)
Jan 02 14:20:08 jfz1r03h11 devstack@placement-api.service[14363]: ERROR oslo_db.sqlalchemy.engines   File "/usr/local/lib/python2.7/dist-packages/pymysql/cursors.py", line 170, in execute
Jan 02 14:20:08 jfz1r03h11 devstack@placement-api.service[14363]: ERROR oslo_db.sqlalchemy.engines     result = self._query(query)
Jan 02 14:20:08 jfz1r03h11 devstack@placement-api.service[14363]: ERROR oslo_db.sqlalchemy.engines   File "/usr/local/lib/python2.7/dist-packages/pymysql/cursors.py", line 328, in _query
Jan 02 14:20:08 jfz1r03h11 devstack@placement-api.service[14363]: ERROR oslo_db.sqlalchemy.engines     conn.query(q)
Jan 02 14:20:08 jfz1r03h11 devstack@placement-api.service[14363]: ERROR oslo_db.sqlalchemy.engines   File "/usr/local/lib/python2.7/dist-packages/pymysql/connections.py", line 517, in query
Jan 02 14:20:08 jfz1r03h11 devstack@placement-api.service[14363]: ERROR oslo_db.sqlalchemy.engines     self._affected_rows = self._read_query_result(unbuffered=unbuffered)
Jan 02 14:20:08 jfz1r03h11 devstack@placement-api.service[14363]: ERROR oslo_db.sqlalchemy.engines   File "/usr/local/lib/python2.7/dist-packages/pymysql/connections.py", line 732, in _read_query_result
Jan 02 14:20:08 jfz1r03h11 devstack@placement-api.service[14363]: ERROR oslo_db.sqlalchemy.engines     result.read()
Jan 02 14:20:08 jfz1r03h11 devstack@placement-api.service[14363]: ERROR oslo_db.sqlalchemy.engines   File "/usr/local/lib/python2.7/dist-packages/pymysql/connections.py", line 1075, in read
Jan 02 14:20:08 jfz1r03h11 devstack@placement-api.service[14363]: ERROR oslo_db.sqlalchemy.engines     first_packet = self.connection._read_packet()
Jan 02 14:20:08 jfz1r03h11 devstack@placement-api.service[14363]: ERROR oslo_db.sqlalchemy.engines   File "/usr/local/lib/python2.7/dist-packages/pymysql/connections.py", line 657, in _read_packet
Jan 02 14:20:08 jfz1r03h11 devstack@placement-api.service[14363]: ERROR oslo_db.sqlalchemy.engines     packet_header = self._read_bytes(4)
Jan 02 14:20:08 jfz1r03h11 devstack@placement-api.service[14363]: ERROR oslo_db.sqlalchemy.engines   File "/usr/local/lib/python2.7/dist-packages/pymysql/connections.py", line 707, in _read_bytes
Jan 02 14:20:08 jfz1r03h11 devstack@placement-api.service[14363]: ERROR oslo_db.sqlalchemy.engines     CR.CR_SERVER_LOST, "Lost connection to MySQL server during query")
Jan 02 14:20:08 jfz1r03h11 devstack@placement-api.service[14363]: ERROR oslo_db.sqlalchemy.engines DBConnectionError: (pymysql.err.OperationalError) (2013, 'Lost connection to MySQL server during query') [SQL: u'SELECT 1'] (Background on this error at: http://sqlalche.me/e/e3q8)
Jan 02 14:20:08 jfz1r03h11 devstack@placement-api.service[14363]: ERROR oslo_db.sqlalchemy.engines 
Jan 02 14:20:08 jfz1r03h11 devstack@placement-api.service[14363]: INFO placement.requestlog [req-6ba7aad8-997a-4851-ae1a-6f60f088f466 req-a7a2f62d-233c-403e-8ccc-b7e49c7a60f8 service placement] 172.16.3.11 "GET /placement/traits?name=in:HW_CPU_X86_SSE2,HW_CPU_X86_SSE,HW_CPU_X86_SVM,HW_CPU_X86_MMX" status: 200 len: 14 microversion: 1.6
Jan 02 14:20:08 jfz1r03h11 devstack@placement-api.service[14363]: [pid: 14376|app: 0|req: 31/546] 172.16.3.11 () {64 vars in 1462 bytes} [Wed Jan  2 14:20:08 2019] GET /placement/traits?name=in:HW_CPU_X86_SSE2,HW_CPU_X86_SSE,HW_CPU_X86_SVM,HW_CPU_X86_MMX => generated 14 bytes in 143 msecs (HTTP/1.1 200) 6 headers in 223 bytes (1 switches on core 0)
Jan 02 14:20:08 jfz1r03h11 devstack@placement-api.service[14363]: DEBUG placement.requestlog [req-6ba7aad8-997a-4851-ae1a-6f60f088f466 req-f1e428fc-1f5a-481a-999a-ad5accb26a5c service placement] Starting request: 172.16.3.11 "PUT /placement/traits/HW_CPU_X86_SSE2" {{(pid=14369) __call__ /opt/stack/placement/placement/requestlog.py:38}}
Jan 02 14:20:08 jfz1r03h11 devstack@placement-api.service[14363]: DEBUG placement.wsgi_wrapper [req-6ba7aad8-997a-4851-ae1a-6f60f088f466 req-f1e428fc-1f5a-481a-999a-ad5accb26a5c service placement] Placement API returning an error response: The trait is invalid. A valid trait must be no longer than 255 characters, start with the prefix "CUSTOM_" and use following characters: "A"-"Z", "0"-"9" and "_" {{(pid=14369) call_func /opt/stack/placement/placement/wsgi_wrapper.py:31}}
Jan 02 14:20:08 jfz1r03h11 devstack@placement-api.service[14363]: INFO placement.requestlog [req-6ba7aad8-997a-4851-ae1a-6f60f088f466 req-f1e428fc-1f5a-481a-999a-ad5accb26a5c service placement] 172.16.3.11 "PUT /placement/traits/HW_CPU_X86_SSE2" status: 400 len: 402 microversion: 1.6
Jan 02 14:20:08 jfz1r03h11 devstack@placement-api.service[14363]: [pid: 14369|app: 0|req: 31/547] 172.16.3.11 () {66 vars in 1392 bytes} [Wed Jan  2 14:20:08 2019] PUT /placement/traits/HW_CPU_X86_SSE2 => generated 402 bytes in 148 msecs (HTTP/1.1 400) 6 headers in 233 bytes (2 switches on core 0)
